Workbook

Sheet 00 Start Here
A1: Enterprise AI Architecture — Owner-Led Learning and Execution Tracker v1.3.0
A2: Objective: learn the business architecture, implementation decisions, testing, deployment, remediation and end-to-end flow. Codex writes approved code; the owner executes commands and owns every decision.
A4: How to use the workbook | E4: Operating rules
A5: 1 | B5: Review dashboard and owner inputs | C5: Choose restart or resume later; preserve historical status until you decide. | E5: MUST — required for the six-week MVP and weekly gate.
A6: 2 | B6: Paste CTX-001 and CTRL-001 | C6: Set the architecture context and the code-only/owner-execution boundary. | E6: SHOULD — hardening or AWS deployment value; defer only with owner-recorded risk.
A7: 3 | B7: Paste one Main Prompt | C7: Codex reviews scope, context, decisions, exact code paths and owner-run validation; no edits yet. | E7: OPTIONAL — learn/adopt only when a measured requirement justifies cost/complexity.
A8: 4 | B8: Review the pre-edit plan | C8: Confirm business purpose, architecture fit, trade-offs, access, testing, deployment, rollback and cost. | E8: Codex writes code; the owner runs every test, deployment, rollback, teardown and access-sensitive command.
A9: 5 | B9: Paste Code Edit Approval | C9: Use Column L. Codex writes approved code/configuration/test code only and runs nothing. | E9: A failure produces diagnosis and one owner command at a time; source fixes require a new Code Edit Approval.
A10: 6 | B10: Receive code and owner guide | C10: Codex provides changed paths, test/deployment commands, remediation guidance and interview learning summary. | E10: Documentation is a separate approved stage and must state business value in clear wording.
A11: 7 | B11: Run owner-led testing/deployment | C11: Use TEST-001. You run one command at a time; Codex explains results and guides failures without executing fixes. | E11: Final approval follows owner testing and document review; Codex never self-approves.
A12: 8 | B12: Paste Document Writing Approval | C12: Use Column M after owner testing. Codex writes only approved business-first documentation/evidence. | E12: Weekly learning is mandatory before progressing: business story, technical deep-dive, layman analogy and interview teach-back.
A13: 9 | B13: Paste Final Approval After Test | C13: Use Column N only after reviewing owner-executed results, approved documentation, rollback/cleanup and the learning summary. Codex then performs only the bounded final-documentation closure; the owner updates Excel afterward. | E13: Editable project inputs — owner maintained
A14: 10 | B14: Update tracker and learn the week | C14: You update status/evidence, complete the weekly checkpoint, then run the mandatory WEEKLY-LEARN-001 teach-back task. | E14: Project start date
E15: Owner | F15: Gyan Prakash Rai
E16: Current week | F16: Week 1
E17: Monthly sandbox budget | F17: TODO
E18: Restart / resume decision | F18: Pending owner decision
A19: Source precedence remains unchanged. This version changes execution ownership and learning controls only: Codex writes approved code; the owner tests, deploys, remediates and approves.

Sheet 01 Dashboard
A1: Execution Dashboard
A2: All KPIs are formula-driven from tracker sheets. Historical status is preserved; the owner executes tests/deployments and updates source records after final approval.
A4: Total steps | D4: Done | G4: Overall progress | J4: Blocked
A5: =COUNTA('02 Master Plan'!$A$6:$A$120) -> 80 | D5: =COUNTIF('02 Master Plan'!$S$6:$S$120,"Done") -> 12 | G5: =IF(A5=0,0,D5/A5) -> 0.15 | J5: =COUNTIF('02 Master Plan'!$S$6:$S$120,"Blocked") -> 0
A7: Open owner TODOs | D7: Tests passed | G7: Decisions approved | J7: Lifecycle tests passed
A8: =COUNTIFS('13 Owner TODOs'!$F$6:$F$80,"<>Done",'13 Owner TODOs'!$A$6:$A$80,"<>") -> 19 | D8: =COUNTIF('11 Test Evidence'!$H$6:$H$80,"Pass") -> 6 | G8: =COUNTIF('12 Decision Log'!$C$6:$C$60,"Baseline Approved")+COUNTIF('12 Decision Log'!$C$6:$C$60,"Approved") -> 18 | J8: =COUNTIFS('11 Test Evidence'!$C$6:$C$80,"Teardown",'11 Test Evidence'!$H$6:$H$80,"Pass") -> 1
A12: Week | B12: Total | C12: Done | D12: Progress | E12: Blocked | G12: Week | H12: Progress
A13: Week 1 | B13: =COUNTIF('02 Master Plan'!$B$6:$B$120,A13) -> 13 | C13: =COUNTIFS('02 Master Plan'!$B$6:$B$120,A13,'02 Master Plan'!$S$6:$S$120,"Done") -> 12 | D13: =IF(B13=0,0,C13/B13) -> 0.92307692 | E13: =COUNTIFS('02 Master Plan'!$B$6:$B$120,A13,'02 Master Plan'!$S$6:$S$120,"Blocked") -> 0 | G13: =A13 -> Week 1 | H13: =D13 -> 0.92307692
A14: Week 2 | B14: =COUNTIF('02 Master Plan'!$B$6:$B$120,A14) -> 13 | C14: =COUNTIFS('02 Master Plan'!$B$6:$B$120,A14,'02 Master Plan'!$S$6:$S$120,"Done") -> 0 | D14: =IF(B14=0,0,C14/B14) -> 0 | E14: =COUNTIFS('02 Master Plan'!$B$6:$B$120,A14,'02 Master Plan'!$S$6:$S$120,"Blocked") -> 0 | G14: =A14 -> Week 2 | H14: =D14 -> 0
A15: Week 3 | B15: =COUNTIF('02 Master Plan'!$B$6:$B$120,A15) -> 13 | C15: =COUNTIFS('02 Master Plan'!$B$6:$B$120,A15,'02 Master Plan'!$S$6:$S$120,"Done") -> 0 | D15: =IF(B15=0,0,C15/B15) -> 0 | E15: =COUNTIFS('02 Master Plan'!$B$6:$B$120,A15,'02 Master Plan'!$S$6:$S$120,"Blocked") -> 0 | G15: =A15 -> Week 3 | H15: =D15 -> 0
A16: Week 4 | B16: =COUNTIF('02 Master Plan'!$B$6:$B$120,A16) -> 13 | C16: =COUNTIFS('02 Master Plan'!$B$6:$B$120,A16,'02 Master Plan'!$S$6:$S$120,"Done") -> 0 | D16: =IF(B16=0,0,C16/B16) -> 0 | E16: =COUNTIFS('02 Master Plan'!$B$6:$B$120,A16,'02 Master Plan'!$S$6:$S$120,"Blocked") -> 0 | G16: =A16 -> Week 4 | H16: =D16 -> 0
A17: Week 5 | B17: =COUNTIF('02 Master Plan'!$B$6:$B$120,A17) -> 14 | C17: =COUNTIFS('02 Master Plan'!$B$6:$B$120,A17,'02 Master Plan'!$S$6:$S$120,"Done") -> 0 | D17: =IF(B17=0,0,C17/B17) -> 0 | E17: =COUNTIFS('02 Master Plan'!$B$6:$B$120,A17,'02 Master Plan'!$S$6:$S$120,"Blocked") -> 0 | G17: =A17 -> Week 5 | H17: =D17 -> 0
A18: Week 6 | B18: =COUNTIF('02 Master Plan'!$B$6:$B$120,A18) -> 14 | C18: =COUNTIFS('02 Master Plan'!$B$6:$B$120,A18,'02 Master Plan'!$S$6:$S$120,"Done") -> 0 | D18: =IF(B18=0,0,C18/B18) -> 0 | E18: =COUNTIFS('02 Master Plan'!$B$6:$B$120,A18,'02 Master Plan'!$S$6:$S$120,"Blocked") -> 0 | G18: =A18 -> Week 6 | H18: =D18 -> 0
A21: Weekly gate interpretation
A22: READY: every MUST task is Done, tests have evidence and the owner signs off.
A23: BLOCKED: stop new prompts; resolve the dependency or explicitly defer with risk/owner/date.
A24: IN PROGRESS: Codex writes approved code only; the owner follows TEST-001 guidance and returns each command result.
A25: Done requires owner-executed validation, approved business-first documentation, rollback/teardown evidence and final owner approval.
A26: Cloud mutations remain manual even when every automated gate passes.

Sheet 02 Master Plan
A1: Master Six-Week Owner-Led Learning Plan — v1.3.0
A2: Historical status is preserved. Codex writes approved code only; the owner executes verification/deployment and completes the weekly learning gate.
A5: Step ID | B5: Week | C5: Seq | D5: Priority | E5: Workstream | F5: Task / Outcome | G5: Why It Matters | H5: Owner | I5: Effort (h) | J5: Prompt ID | K5: User TODO IDs | L5: Acceptance Criteria | M5: Owner Verification Command | N5: Expected Result | O5: Evidence Path | P5: Decision ID | Q5: Dependency | R5: Rollback / Teardown | S5: Status | T5: Notes | U5: Task Context
A6: W1-01 | B6: Week 1 | C6: 1 | D6: MUST | E6: Scope | F6: Confirm the first use case, user group, exclusions and measurable MVP outcome. | G6: A narrow use case prevents a platform-without-a-problem and sets evaluation truth. | H6: User | I6: 1 | J6: W1-MVP-001 | K6: USE-001, DATA-001, EVAL-001 | L6: One approved one-page scope and 5 representative questions. | M6: Owner review of docs/features/MVP-001.md | N6: Scope, exclusions and success measures approved. | O6: docs/features/MVP-001.md | P6: ADR-001 | Q6: None | R6: Revert scope file before implementation begins. | S6: Done | T6: Use W1-MVP-001. Approve five starter questions now; the full 25+ golden dataset is completed under W3-002 in Week 3. | Implementation commit 210381c3ddbc9aab83ccaeb11a59db8d8dad549b; owner approval date 2026-08-18; owner reaffirmed 2026-08-18T16:01:18Z. | U6: Week 1 business/decision documentation task in Scope. The owner provides or approves the facts; after Document Writing Approval, Codex may draft only the approved business-first documentation. No code or command execution is permitted. Business value: A narrow use case prevents a platform-without-a-problem and sets evaluation truth. Interview focus: explain the decision, its alternatives and downstream impact.
A7: W1-02 | B7: Week 1 | C7: 2 | D7: MUST | E7: Governance | F7: Record source precedence: v1.1 controls override older schedule while preserving technical prompts. | G7: Prevents Codex and coach from following conflicting weekly sequences. | H7: User (execute) + Codex (guide/code) | I7: 0.5 | J7: W1-GOV-001 | K7: None | L7: Decision recorded and referenced by all feature prompts. | M7: Review docs/adr/ADR-000-source-precedence.md | N7: v1.1 is named implementation authority. | O7: docs/adr/ADR-000-source-precedence.md | P7: ADR-016 | Q7: W1-01 | R7: Restore prior ADR only through reviewed superseding decision. | S7: Done | T7: Use W1-GOV-001. Create ADR-000 only; docs/codex files are not prerequisites for this task. | Implementation commit 210381c3ddbc9aab83ccaeb11a59db8d8dad549b; owner approval date 2026-08-18; owner reaffirmed 2026-08-18T16:01:18Z. | U7: Week 1 business/decision documentation task in Governance. The owner provides or approves the facts; after Document Writing Approval, Codex may draft only the approved business-first documentation. No code or command execution is permitted. Business value: Prevents Codex and coach from following conflicting weekly sequences. Interview focus: explain the decision, its alternatives and downstream impact.
A8: W1-03 | B8: Week 1 | C8: 3 | D8: MUST | E8: Repository | F8: Create the monorepo and documentation/evidence structure. | G8: Gives every change an auditable home and supports clean ownership. | H8: Codex (code) + User (execute) | I8: 1.5 | J8: W1-001 | K8: TAG-001 | L8: Required folders, README and Makefile exist. | M8: find . -maxdepth 3 -type d | sort | N8: Layout matches blueprint; no unrelated files changed. | O8: docs/test-evidence/W1-03-layout.txt | P8: ADR-016 | Q8: W1-02 | R8: Delete only newly created empty skeleton paths after diff review. | S8: Done | T8: Implementation commit 210381c3ddbc9aab83ccaeb11a59db8d8dad549b; owner approval date 2026-08-18; owner reaffirmed 2026-08-18T16:01:18Z. | U8: Week 1 Repository task in the end-to-end architecture. After Code Edit Approval, Codex writes only the approved code/configuration/test code for “Create the monorepo and documentation/evidence structure.”; you run the verification/deployment commands and return the results. Business value: Gives every change an auditable home and supports clean ownership. Interview focus: explain where this component sits, how it fails safely and how it is rolled back.
A9: W1-04 | B9: Week 1 | C9: 4 | D9: MUST | E9: Traceability | F9: Create feature-matrix.yaml and the first feature record. | G9: Links purpose, files, tests, cost, approval, rollback and teardown. | H9: Codex (code) + User (execute) | I9: 1 | J9: W1-001 | K9: USE-001, TAG-001 | L9: Schema validates and feature MVP-001 is planned. | M9: python tools/validate_feature_matrix.py | N9: Validation exits 0; missing required fields fail. | O9: docs/test-evidence/W1-04-feature-matrix.json | P9: ADR-016 | Q9: W1-03 | R9: Restore previous matrix version from Git. | S9: Done | T9: Implementation commit 210381c3ddbc9aab83ccaeb11a59db8d8dad549b; owner approval date 2026-08-18; owner reaffirmed 2026-08-18T16:01:18Z. | U9: Week 1 Traceability task in the end-to-end architecture. After Code Edit Approval, Codex writes only the approved code/configuration/test code for “Create feature-matrix.yaml and the first feature record.”; you run the verification/deployment commands and return the results. Business value: Links purpose, files, tests, cost, approval, rollback and teardown. Interview focus: explain where this component sits, how it fails safely and how it is rolled back.
A10: W1-05 | B10: Week 1 | C10: 5 | D10: MUST | E10: Python foundation | F10: Create reproducible dependencies and typed configuration. | G10: Fail-fast configuration and portable dependencies reduce hidden runtime risk. | H10: Codex (code) + User (execute) | I10: 1.5 | J10: W1-002 | K10: AWS-002, BED-001, EMB-001 | L10: pip install succeeds; config tests pass offline. | M10: pip install -r requirements.txt && pytest tests/unit/test_config.py -q | N10: No paid/network dependency in unit tests; TODOs remain non-secret. | O10: docs/test-evidence/W1-05-config.txt | P10: ADR-002 | Q10: W1-03 | R10: Revert dependency/config commit and recreate virtual environment. | S10: Done | T10: Implementation commit 210381c3ddbc9aab83ccaeb11a59db8d8dad549b; owner approval date 2026-08-18; owner reaffirmed 2026-08-18T16:01:18Z. | U10: Week 1 Python foundation task in the end-to-end architecture. After Code Edit Approval, Codex writes only the approved code/configuration/test code for “Create reproducible dependencies and typed configuration.”; you run the verification/deployment commands and return the results. Business value: Fail-fast configuration and portable dependencies reduce hidden runtime risk. Interview focus: explain where this component sits, how it fails safely and how it is rolled back.
A11: W1-06 | B11: Week 1 | C11: 6 | D11: MUST | E11: Testing | F11: Create pytest layers, deterministic fakes and evidence capture. | G11: Testing is a feature gate, not an afterthought. | H11: Codex (code) + User (execute) | I11: 1.25 | J11: W1-003 | K11: None | L11: Markers and sample feature test run locally. | M11: pytest tests/unit tests/feature -q | N11: Tests pass; evidence metadata excludes secrets/content. | O11: docs/test-evidence/W1-06-tests.json | P11: ADR-017 | Q11: W1-04,W1-05 | R11: Revert test framework commit; no platform resources exist. | S11: Done | T11: Implementation commit 210381c3ddbc9aab83ccaeb11a59db8d8dad549b; owner approval date 2026-08-18; owner reaffirmed 2026-08-18T16:01:18Z. | U11: Week 1 Testing task in the end-to-end architecture. After Code Edit Approval, Codex writes only the approved code/configuration/test code for “Create pytest layers, deterministic fakes and evidence capture.”; you run the verification/deployment commands and return the results. Business value: Testing is a feature gate, not an afterthought. Interview focus: explain where this component sits, how it fails safely and how it is rolled back.
A12: W1-07 | B12: Week 1 | C12: 7 | D12: MUST | E12: Developer controls | F12: Add Make targets for preflight, test, scan, plan, rollback, destroy-plan and verify-clean. | G12: A single, reviewable command vocabulary keeps user and Codex synchronized. | H12: Codex (code) + User (execute) | I12: 1 | J12: W1-001 | K12: None | L12: Make help documents safe commands; mutating commands are gated. | M12: make help && make preflight | N12: Preflight passes; apply/destroy are never default dependencies. | O12: docs/test-evidence/W1-07-make.txt | P12: ADR-010, ADR-011 | Q12: W1-03 | R12: Revert Makefile changes. | S12: Done | T12: Implementation commit 210381c3ddbc9aab83ccaeb11a59db8d8dad549b; owner approval date 2026-08-18; owner reaffirmed 2026-08-18T16:01:18Z. | U12: Week 1 Developer controls task in the end-to-end architecture. After Code Edit Approval, Codex writes only the approved code/configuration/test code for “Add Make targets for preflight, test, scan, plan, rollback, destroy-plan and verify-clean.”; you run the verification/deployment commands and return the results. Business value: A single, reviewable command vocabulary keeps user and Codex synchronized. Interview focus: explain where this component sits, how it fails safely and how it is rolled back.
A13: W1-08 | B13: Week 1 | C13: 8 | D13: MUST | E13: DevSecOps | F13: Add pre-commit formatting, linting and secret scanning baseline. | G13: Shift-left checks stop secrets and poor-quality changes before PR. | H13: Codex (code) + User (execute) | I13: 1 | J13: W1-003 | K13: SEC-003 | L13: Insecure secret fixture is blocked without committing a real secret. | M13: pre-commit run --all-files | N13: All checks pass on source; synthetic fixture produces expected failure. | O13: docs/test-evidence/W1-08-precommit.txt | P13: ADR-017 | Q13: W1-05 | R13: Revert hooks only after owner review; rotate any accidentally exposed credential. | S13: Done | T13: Implementation commit 210381c3ddbc9aab83ccaeb11a59db8d8dad549b; owner approval date 2026-08-18; owner reaffirmed 2026-08-18T16:01:18Z. | U13: Week 1 DevSecOps task in the end-to-end architecture. After Code Edit Approval, Codex writes only the approved code/configuration/test code for “Add pre-commit formatting, linting and secret scanning baseline.”; you run the verification/deployment commands and return the results. Business value: Shift-left checks stop secrets and poor-quality changes before PR. Interview focus: explain where this component sits, how it fails safely and how it is rolled back.
A14: W1-09 | B14: Week 1 | C14: 9 | D14: MUST | E14: Terraform lifecycle | F14: Separate infra/bootstrap from infra/environments/sandbox and document state removal last. | G14: A platform cannot fully disappear if its state backend is embedded in the same lifecycle. | H14: Codex (code) + User (execute) | I14: 1.25 | J14: W1-004 | K14: AWS-001, AWS-002, TAG-001 | L14: Two roots validate as skeletons and dependency order is documented. | M14: terraform -chdir=infra/bootstrap fmt -check && terraform -chdir=infra/environments/sandbox fmt -check | N14: No resource apply; backend/platform boundaries are explicit. | O14: docs/test-evidence/W1-09-roots.txt | P14: ADR-009 | Q14: W1-03 | R14: Revert Terraform skeleton; no state exists yet. | S14: Done | T14: Implementation commit 210381c3ddbc9aab83ccaeb11a59db8d8dad549b; owner approval date 2026-08-18; owner reaffirmed 2026-08-18T16:01:18Z. | W1-004 historical disclosure preserved: commit d3e5ad182fac38dbf166c6ce15b8ade8868379da contained 34 intended paths plus 1 owner workbook path; consolidated commit 210381c3ddbc9aab83ccaeb11a59db8d8dad549b excludes the workbook. | U14: Week 1 Terraform lifecycle task in the end-to-end architecture. After Code Edit Approval, Codex writes only the approved code/configuration/test code for “Separate infra/bootstrap from infra/environments/sandbox and document state removal last.”; you run the verification/deployment commands and return the results. Business value: A platform cannot fully disappear if its state backend is embedded in the same lifecycle. Interview focus: explain where this component sits, how it fails safely and how it is rolled back.
A15: W1-10 | B15: Week 1 | C15: 10 | D15: MUST | E15: Reversibility | F15: Create platformctl command contracts with dry-run and approvals. | G15: Deploy, rollback and teardown need distinct safe semantics. | H15: Codex (code) + User (execute) | I15: 1.5 | J15: W1-004 | K15: DEST-001, KMS-001 | L15: CLI help and unit tests prove confirmation/approval gates. | M15: python -m tools.platformctl --help && pytest tests/unit/test_platformctl.py -q | N15: No command mutates by default; missing approval fails closed. | O15: docs/test-evidence/W1-10-platformctl.txt | P15: ADR-010, ADR-011, ADR-012 | Q15: W1-09 | R15: Revert CLI commit; no cloud mutation is allowed. | S15: Done | T15: Implementation commit 210381c3ddbc9aab83ccaeb11a59db8d8dad549b; owner approval date 2026-08-18; owner reaffirmed 2026-08-18T16:01:18Z. | W1-004 historical disclosure preserved: commit d3e5ad182fac38dbf166c6ce15b8ade8868379da contained 34 intended paths plus 1 owner workbook path; consolidated commit 210381c3ddbc9aab83ccaeb11a59db8d8dad549b excludes the workbook. | U15: Week 1 Reversibility task in the end-to-end architecture. After Code Edit Approval, Codex writes only the approved code/configuration/test code for “Create platformctl command contracts with dry-run and approvals.”; you run the verification/deployment commands and return the results. Business value: Deploy, rollback and teardown need distinct safe semantics. Interview focus: explain where this component sits, how it fails safely and how it is rolled back.
A16: W1-11 | B16: Week 1 | C16: 11 | D16: MUST | E16: Cleanup verification | F16: Implement mocked tag and service-specific residual checks. | G16: Tag-only discovery misses some resources; native checks close the gap. | H16: Codex (code) + User (execute) | I16: 1 | J16: W1-004 | K16: TAG-001, KMS-001 | L16: Mock orphan makes verify-clean fail; PendingDeletion key is documented exception. | M16: pytest tests/teardown -q | N16: Expected pass/fail matrix is recorded. | O16: docs/test-evidence/W1-11-cleanup.json | P16: ADR-013, ADR-014 | Q16: W1-10 | R16: Revert verifier implementation; keep the control requirement. | S16: Done | T16: Implementation commit 210381c3ddbc9aab83ccaeb11a59db8d8dad549b; owner approval date 2026-08-18; owner reaffirmed 2026-08-18T16:01:18Z. | W1-004 historical disclosure preserved: commit d3e5ad182fac38dbf166c6ce15b8ade8868379da contained 34 intended paths plus 1 owner workbook path; consolidated commit 210381c3ddbc9aab83ccaeb11a59db8d8dad549b excludes the workbook. | U16: Week 1 Cleanup verification task in the end-to-end architecture. After Code Edit Approval, Codex writes only the approved code/configuration/test code for “Implement mocked tag and service-specific residual checks.”; you run the verification/deployment commands and return the results. Business value: Tag-only discovery misses some resources; native checks close the gap. Interview focus: explain where this component sits, how it fails safely and how it is rolled back.
A17: W1-12 | B17: Week 1 | C17: 12 | D17: MUST | E17: Checkpoint | F17: Review diffs, architecture decisions, test evidence and Week 2 readiness. | G17: Owner approval is the stop point between features/weeks. | H17: User | I17: 1 | J17: WEEKLY-REVIEW-001 | K17: All Week 1 TODOs | L17: Every MUST step is Done; no blocker or unapproved scope remains. | M17: make preflight && make test | N17: Owner sign-off recorded with outstanding items explicitly deferred. | O17: docs/deployment-records/W1-signoff.md | P17: ADR-016 | Q17: W1-01:W1-11 | R17: No Week 2 prompt is used until gaps are resolved. | S17: Done | T17: W1-12 readiness PASS; final Week 1 sign-off APPROVED by Gyan Prakash Rai at 2026-08-19T00:10:55+08:00 (Asia/Singapore); sign-off evidence docs/deployment-records/W1-signoff.md; implementation commit 210381c3ddbc9aab83ccaeb11a59db8d8dad549b. | U17: Week 1 business/decision documentation task in Checkpoint. The owner provides or approves the facts; after Document Writing Approval, Codex may draft only the approved business-first documentation. No code or command execution is permitted. Business value: Owner approval is the stop point between features/weeks. Interview focus: explain the decision, its alternatives and downstream impact.
A18: W1-13 | B18: Week 1 | C18: 13 | D18: MUST | E18: Weekly learning | F18: Complete the Week 1 business, architecture and interview teach-back. | G18: Turns governance, repository, test and lifecycle controls into an explainable architecture story. | H18: User (execute) + Codex (guide/code) | I18: 1 | J18: WEEKLY-LEARN-001 | K18: None | L18: Owner explains the Week 1 business outcome, control flow, decisions, failure boundaries and three interview answers without reading code. | M18: Owner teach-back; no command | N18: Business summary, technical deep-dive, layman analogy, decision recap and interview Q&A completed. | O18: docs/learning/W1-learning-review.md | P18: Existing Week 1 ADRs | Q18: W1-12 | R18: No runtime rollback; revise the learning note through document approval if inaccurate. | S18: Not Started | T18: Added in v1.3.0; historical Week 1 completion records remain unchanged. | U18: Week 1 learning gate after all implementation and checkpoint work. Codex teaches the business outcome and architecture; the owner completes a teach-back and interview practice. No runtime action is permitted. Business value: converts completed work into reusable understanding and decision ownership.
A19: W2-01 | B19: Week 2 | C19: 1 | D19: MUST | E19: Data contracts | F19: Implement provider-neutral document, chunk, query, answer and citation models. | G19: Stable domain types make vector and LLM backends replaceable. | H19: Codex (code) + User (execute) | I19: 1 | J19: W2-001 | K19: DATA-002, SEC-001 | L19: Models validate required identity/classification metadata. | M19: pytest tests/unit/test_models.py -q | N19: Invalid tenant/classification input fails. | O19: docs/test-evidence/W2-01-models.txt | P19: ADR-002 | Q19: W1-13 | R19: Revert model commit; no stored vectors affected. | S19: Not Started | U19: Week 2 Data contracts task in the end-to-end architecture. After Code Edit Approval, Codex writes only the approved code/configuration/test code for “Implement provider-neutral document, chunk, query, answer and citation models.”; you run the verification/deployment commands and return the results. Business value: Stable domain types make vector and LLM backends replaceable. Interview focus: explain where this component sits, how it fails safely and how it is rolled back.
A20: W2-02 | B20: Week 2 | C20: 2 | D20: MUST | E20: Vector interface | F20: Define VectorStore protocol and in-memory fake with contract tests. | G20: Business logic must not depend on Qdrant/OpenSearch SDK objects. | H20: Codex (code) + User (execute) | I20: 1.25 | J20: W2-001 | K20: None | L20: Fake passes all contract tests. | M20: pytest tests/contract/test_vector_store.py -q | N20: Protocol behavior and normalized errors are stable. | O20: docs/test-evidence/W2-02-vector-contract.txt | P20: ADR-002, ADR-003 | Q20: W2-01 | R20: Revert interface only before downstream adapters merge. | S20: Not Started | U20: Week 2 Vector interface task in the end-to-end architecture. After Code Edit Approval, Codex writes only the approved code/configuration/test code for “Define VectorStore protocol and in-memory fake with contract tests.”; you run the verification/deployment commands and return the results. Business value: Business logic must not depend on Qdrant/OpenSearch SDK objects. Interview focus: explain where this component sits, how it fails safely and how it is rolled back.
A21: W2-03 | B21: Week 2 | C21: 3 | D21: MUST | E21: Local platform | F21: Start pinned Qdrant through Docker Compose with healthcheck. | G21: A real client/server vector store gives useful local integration evidence. | H21: Codex (code) + User (execute) | I21: 1 | J21: W2-001 | K21: None | L21: Qdrant becomes healthy without an embedded credential. | M21: docker compose up -d qdrant && docker compose ps | N21: Service is healthy; image version is pinned. | O21: docs/test-evidence/W2-03-qdrant.txt | P21: ADR-003 | Q21: W1-12 | R21: docker compose down -v; verify no project volume/network. | S21: Not Started | U21: Week 2 Local platform task in the end-to-end architecture. After Code Edit Approval, Codex writes only the approved code/configuration/test code for “Start pinned Qdrant through Docker Compose with healthcheck.”; you run the verification/deployment commands and return the results. Business value: A real client/server vector store gives useful local integration evidence. Interview focus: explain where this component sits, how it fails safely and how it is rolled back.
A22: W2-04 | B22: Week 2 | C22: 4 | D22: MUST | E22: Vector adapters | F22: Implement Qdrant adapter and OpenSearch adapter boundary. | G22: Local and AWS retrieval must satisfy the same contract. | H22: Codex (code) + User (execute) | I22: 1.5 | J22: W2-001 | K22: AWS-002, NET-001 | L22: Fake/Qdrant tests pass; AWS tests remain marked/skipped. | M22: pytest tests/contract tests/integration/test_qdrant.py -q | N22: No vendor object leaks; timeouts and filters are applied. | O22: docs/test-evidence/W2-04-adapters.txt | P22: ADR-003 | Q22: W2-02,W2-03 | R22: Delete test collection and restore previous adapter version. | S22: Not Started | U22: Week 2 Vector adapters task in the end-to-end architecture. After Code Edit Approval, Codex writes only the approved code/configuration/test code for “Implement Qdrant adapter and OpenSearch adapter boundary.”; you run the verification/deployment commands and return the results. Business value: Local and AWS retrieval must satisfy the same contract. Interview focus: explain where this component sits, how it fails safely and how it is rolled back.
A23: W2-05 | B23: Week 2 | C23: 5 | D23: MUST | E23: Embeddings | F23: Implement sentence-transformer and deterministic fake embedders. | G23: Local CPU embeddings avoid a paid dependency while preserving provider exit. | H23: Codex (code) + User (execute) | I23: 1.25 | J23: W2-002 | K23: EMB-001 | L23: Batch, normalization and dimension mismatch tests pass. | M23: pytest tests/unit/test_embedder.py -q | N23: Unit tests make no model download; integration model is explicit. | O23: docs/test-evidence/W2-05-embedder.txt | P23: ADR-002 | Q23: W2-01 | R23: Restore previous model configuration and recreate collection if dimension changed. | S23: Not Started | U23: Week 2 Embeddings task in the end-to-end architecture. After Code Edit Approval, Codex writes only the approved code/configuration/test code for “Implement sentence-transformer and deterministic fake embedders.”; you run the verification/deployment commands and return the results. Business value: Local CPU embeddings avoid a paid dependency while preserving provider exit. Interview focus: explain where this component sits, how it fails safely and how it is rolled back.
A24: W2-06 | B24: Week 2 | C24: 6 | D24: MUST | E24: Ingestion | F24: Implement validation, hashing, normalization and deterministic token chunking. | G24: Reproducible chunk IDs/versioning make re-index and deletion safe. | H24: Codex (code) + User (execute) | I24: 1.5 | J24: W2-003 | K24: DATA-001, DATA-002 | L24: Same input produces same IDs; changed version is distinguishable. | M24: pytest tests/unit/test_chunking.py tests/unit/test_ingestion.py -q | N24: Size/type failures quarantine; no raw content in logs. | O24: docs/test-evidence/W2-06-ingestion.txt | P24: ADR-017 | Q24: W2-01,W2-05 | R24: Delete affected document version and re-ingest last approved manifest. | S24: Not Started | U24: Week 2 Ingestion task in the end-to-end architecture. After Code Edit Approval, Codex writes only the approved code/configuration/test code for “Implement validation, hashing, normalization and deterministic token chunking.”; you run the verification/deployment commands and return the results. Business value: Reproducible chunk IDs/versioning make re-index and deletion safe. Interview focus: explain where this component sits, how it fails safely and how it is rolled back.
A25: W2-07 | B25: Week 2 | C25: 7 | D25: MUST | E25: Privacy | F25: Add replaceable Presidio PII detection/redaction hook. | G25: PII handling belongs before indexing and telemetry. | H25: Codex (code) + User (execute) | I25: 1 | J25: W2-003 | K25: DATA-003 | L25: Configured PII is redacted/quarantined and never appears in evidence logs. | M25: pytest tests/security/test_pii.py -q | N25: Synthetic PII fixture is handled as policy states. | O25: docs/test-evidence/W2-07-pii.txt | P25: ADR-006 | Q25: W2-06 | R25: Delete derived chunks; restore approved unredacted source only in controlled location. | S25: Not Started | U25: Week 2 Privacy task in the end-to-end architecture. After Code Edit Approval, Codex writes only the approved code/configuration/test code for “Add replaceable Presidio PII detection/redaction hook.”; you run the verification/deployment commands and return the results. Business value: PII handling belongs before indexing and telemetry. Interview focus: explain where this component sits, how it fails safely and how it is rolled back.
A26: W2-08 | B26: Week 2 | C26: 8 | D26: MUST | E26: Authorization | F26: Enforce tenant/classification filters before vector search. | G26: The model cannot be trusted to enforce access control. | H26: Codex (code) + User (execute) | I26: 1 | J26: W2-001 | K26: SEC-001 | L26: Cross-tenant query returns zero unauthorized chunks. | M26: pytest tests/security/test_tenant_isolation.py -q | N26: 100% isolation test passes. | O26: docs/test-evidence/W2-08-isolation.txt | P26: ADR-006 | Q26: W2-04 | R26: Disable retrieval endpoint and restore last-known-good filter implementation. | S26: Not Started | U26: Week 2 Authorization task in the end-to-end architecture. After Code Edit Approval, Codex writes only the approved code/configuration/test code for “Enforce tenant/classification filters before vector search.”; you run the verification/deployment commands and return the results. Business value: The model cannot be trusted to enforce access control. Interview focus: explain where this component sits, how it fails safely and how it is rolled back.
A27: W2-09 | B27: Week 2 | C27: 9 | D27: MUST | E27: Feature proof | F27: Ingest approved sample corpus and verify top-5 retrieval. | G27: This is the first measurable RAG foundation outcome. | H27: User (execute) + Codex (guide/code) | I27: 1 | J27: W2-004 | K27: DATA-001, EVAL-001 | L27: Expected source appears in top 5 for representative questions. | M27: python -m enterprise_ai.ingestion.pipeline ingest --source data/sample --tenant demo && pytest tests/feature/test_local_retrieval.py -q | N27: Manifest, retrieval scores and source IDs are captured. | O27: docs/test-evidence/W2-09-retrieval.json | P27: ADR-003, ADR-017 | Q27: W2-03:W2-08 | R27: Delete test collection/volume and restore previous config. | S27: Not Started | U27: Week 2 Feature proof task in the end-to-end architecture. After Code Edit Approval, Codex writes only the approved code/configuration/test code for “Ingest approved sample corpus and verify top-5 retrieval.”; you run the verification/deployment commands and return the results. Business value: This is the first measurable RAG foundation outcome. Interview focus: explain where this component sits, how it fails safely and how it is rolled back.
A28: W2-10 | B28: Week 2 | C28: 10 | D28: MUST | E28: Reversibility | F28: Run local deploy, rollback and complete removal drill. | G28: A working feature is incomplete until it can be removed cleanly. | H28: User (execute) + Codex (guide/code) | I28: 1 | J28: W2-004 | K28: DEST-001 | L28: Previous configuration works after rollback; teardown leaves no local residue. | M28: make rollback-local && make destroy-local && make verify-clean-local | N28: No project container, volume or network remains. | O28: docs/rollback-records/W2-local.md | P28: ADR-012, ADR-013 | Q28: W2-09 | R28: Recreate from pinned Compose/config and re-run feature test. | S28: Not Started | U28: Week 2 Reversibility task in the end-to-end architecture. After Code Edit Approval, Codex writes only the approved code/configuration/test code for “Run local deploy, rollback and complete removal drill.”; you run the verification/deployment commands and return the results. Business value: A working feature is incomplete until it can be removed cleanly. Interview focus: explain where this component sits, how it fails safely and how it is rolled back.
A29: W2-11 | B29: Week 2 | C29: 11 | D29: SHOULD | E29: Learning checkpoint | F29: Explain embeddings, cosine similarity, chunk size/overlap and metadata filtering. | G29: The workbook is also an interview/reference learning plan. | H29: User | I29: 0.75 | J29: W2-LEARN-001 | K29: None | L29: Five-minute explanation uses current implementation evidence. | M29: Record explanation notes in docs/architecture/local-retrieval.md | N29: Explanation connects decisions to quality, security and cost. | O29: docs/architecture/local-retrieval.md | P29: ADR-002, ADR-003, ADR-006 | Q29: W2-09 | R29: Revise ADR/notes; do not change code without a feature cycle. | S29: Not Started | U29: Week 2 owner decision/checkpoint in Learning checkpoint. You choose, approve or execute “Explain embeddings, cosine similarity, chunk size/overlap and metadata filtering.” because the decision affects downstream architecture and risk. Codex explains alternatives and may draft approved wording only under the proper approval stage. Business value: The workbook is also an interview/reference learning plan. Interview focus: explain the decision, trade-off and downstream consequence.
A30: W2-12 | B30: Week 2 | C30: 12 | D30: MUST | E30: Checkpoint | F30: Approve local retrieval gate and Week 3 inputs. | G30: Prevents LLM work from hiding retrieval defects. | H30: User | I30: 0.75 | J30: WEEKLY-REVIEW-001 | K30: BED-001, EVAL-001 | L30: All MUST tests and cleanup evidence pass. | M30: make test && make verify-clean-local | N30: Owner sign-off; Bedrock/evaluation TODOs resolved or explicitly mocked. | O30: docs/deployment-records/W2-signoff.md | P30: ADR-016 | Q30: W2-01:W2-11 | R30: Remain on local retrieval until the gate passes. | S30: Not Started | U30: Week 2 business/decision documentation task in Checkpoint. The owner provides or approves the facts; after Document Writing Approval, Codex may draft only the approved business-first documentation. No code or command execution is permitted. Business value: Prevents LLM work from hiding retrieval defects. Interview focus: explain the decision, its alternatives and downstream impact.
A31: W2-13 | B31: Week 2 | C31: 13 | D31: MUST | E31: Weekly learning | F31: Complete the Week 2 local retrieval business, architecture and interview teach-back. | G31: Converts vector retrieval, ingestion, privacy and authorization work into an end-to-end business explanation. | H31: User (execute) + Codex (guide/code) | I31: 1 | J31: WEEKLY-LEARN-001 | K31: None | L31: Owner explains document-to-vector-to-authorized-retrieval flow, Qdrant role, failure handling and three interview answers. | M31: Owner teach-back; no command | N31: Business summary, technical deep-dive, layman analogy, decision recap and interview Q&A completed. | O31: docs/learning/W2-learning-review.md | P31: ADR-002, ADR-003, ADR-006 | Q31: W2-12 | R31: No runtime rollback; revise the learning note through document approval if inaccurate. | S31: Not Started | T31: Mandatory learning gate before Week 3. | U31: Week 2 learning gate after all implementation and checkpoint work. Codex teaches the business outcome and architecture; the owner completes a teach-back and interview practice. No runtime action is permitted. Business value: converts completed work into reusable understanding and decision ownership.
A32: W3-01 | B32: Week 3 | C32: 1 | D32: MUST | E32: LLM contract | F32: Create provider-neutral chat/tool/usage types and fake provider. | G32: RAG logic should not depend on Bedrock response formats. | H32: Codex (code) + User (execute) | I32: 1 | J32: W3-001 | K32: BED-001 | L32: Fake tests cover success, timeout and malformed response. | M32: pytest tests/unit/test_llm_provider.py -q | N32: Normalized errors and usage fields are stable. | O32: docs/test-evidence/W3-01-llm-contract.txt | P32: ADR-002, ADR-004 | Q32: W2-13 | R32: Switch configuration back to fake provider. | S32: Not Started | U32: Week 3 LLM contract task in the end-to-end architecture. After Code Edit Approval, Codex writes only the approved code/configuration/test code for “Create provider-neutral chat/tool/usage types and fake provider.”; you run the verification/deployment commands and return the results. Business value: RAG logic should not depend on Bedrock response formats. Interview focus: explain where this component sits, how it fails safely and how it is rolled back.
A33: W3-02 | B33: Week 3 | C33: 2 | D33: MUST | E33: AWS AI adapter | F33: Implement Bedrock adapter behind marked integration tests. | G33: Bedrock is the primary AWS model boundary without GPU operations. | H33: Codex (code) + User (execute) | I33: 1.25 | J33: W3-001 | K33: AWS-002, BED-001 | L33: Adapter has deadlines/retry caps and no hard-coded model ID. | M33: pytest tests/unit/test_bedrock_adapter.py -q | N33: Offline tests pass; live test is skipped unless explicitly enabled. | O33: docs/test-evidence/W3-02-bedrock.txt | P33: ADR-004 | Q33: W3-01 | R33: Set LLM_PROVIDER=fake; revoke test session if created. | S33: Not Started | U33: Week 3 AWS AI adapter task in the end-to-end architecture. After Code Edit Approval, Codex writes only the approved code/configuration/test code for “Implement Bedrock adapter behind marked integration tests.”; you run the verification/deployment commands and return the results. Business value: Bedrock is the primary AWS model boundary without GPU operations. Interview focus: explain where this component sits, how it fails safely and how it is rolled back.
A34: W3-03 | B34: Week 3 | C34: 3 | D34: MUST | E34: Prompt boundary | F34: Create versioned evidence-bound prompt template. | G34: Retrieved documents are data, never instructions. | H34: Codex (code) + User (execute) | I34: 0.75 | J34: W3-001 | K34: None | L34: Prompt clearly delimits evidence and demands citations/abstention. | M34: pytest tests/unit/test_prompt_template.py -q | N34: Injection fixture cannot override system policy. | O34: docs/test-evidence/W3-03-prompt.txt | P34: ADR-006, ADR-017 | Q34: W3-01 | R34: Restore previous approved prompt version. | S34: Not Started | U34: Week 3 Prompt boundary task in the end-to-end architecture. After Code Edit Approval, Codex writes only the approved code/configuration/test code for “Create versioned evidence-bound prompt template.”; you run the verification/deployment commands and return the results. Business value: Retrieved documents are data, never instructions. Interview focus: explain where this component sits, how it fails safely and how it is rolled back.
A35: W3-04 | B35: Week 3 | C35: 4 | D35: MUST | E35: RAG pipeline | F35: Authorize, retrieve, grade, generate and validate citations. | G35: This is the core safe-answer path. | H35: Codex (code) + User (execute) | I35: 1.5 | J35: W3-001 | K35: RAG-001 | L35: Structured Answer contains only supplied source IDs. | M35: pytest tests/unit/test_rag_pipeline.py -q | N35: Good evidence answers; low evidence abstains. | O35: docs/test-evidence/W3-04-rag.txt | P35: ADR-006, ADR-017 | Q35: W3-01:W3-03,W2-09 | R35: Switch to last-known-good prompt/model/retriever configuration. | S35: Not Started | U35: Week 3 RAG pipeline task in the end-to-end architecture. After Code Edit Approval, Codex writes only the approved code/configuration/test code for “Authorize, retrieve, grade, generate and validate citations.”; you run the verification/deployment commands and return the results. Business value: This is the core safe-answer path. Interview focus: explain where this component sits, how it fails safely and how it is rolled back.
A36: W3-05 | B36: Week 3 | C36: 5 | D36: MUST | E36: Guardrails | F36: Add deterministic input/output/citation safety checks. | G36: Deterministic policy must surround probabilistic generation. | H36: Codex (code) + User (execute) | I36: 1 | J36: W3-003 | K36: SEC-001, DATA-002 | L36: Malformed, unauthorized and uncited outputs fail safely. | M36: pytest tests/security tests/unit/test_guardrails.py -q | N36: Security suite passes with redacted logs. | O36: docs/test-evidence/W3-05-guardrails.txt | P36: ADR-006 | Q36: W3-04 | R36: Disable affected model route and return safe refusal. | S36: Not Started | U36: Week 3 Guardrails task in the end-to-end architecture. After Code Edit Approval, Codex writes only the approved code/configuration/test code for “Add deterministic input/output/citation safety checks.”; you run the verification/deployment commands and return the results. Business value: Deterministic policy must surround probabilistic generation. Interview focus: explain where this component sits, how it fails safely and how it is rolled back.
A37: W3-06 | B37: Week 3 | C37: 6 | D37: MUST | E37: Evaluation data | F37: Create 25+ golden cases with sources, facts, tenant and safety tags. | G37: Quality thresholds require versioned, representative truth data. | H37: User | I37: 1.25 | J37: W3-002 | K37: EVAL-001, DATA-001 | L37: Dataset passes schema and privacy review. | M37: python tools/validate_eval_dataset.py configs/eval/golden.jsonl | N37: 25+ valid cases; no prohibited data. | O37: docs/test-evidence/W3-06-golden.txt | P37: ADR-017 | Q37: W2-09 | R37: Revert dataset version; never silently edit expected answers. | S37: Not Started | U37: Week 3 owner decision/checkpoint in Evaluation data. You choose, approve or execute “Create 25+ golden cases with sources, facts, tenant and safety tags.” because the decision affects downstream architecture and risk. Codex explains alternatives and may draft approved wording only under the proper approval stage. Business value: Quality thresholds require versioned, representative truth data. Interview focus: explain the decision, trade-off and downstream consequence.
A38: W3-07 | B38: Week 3 | C38: 7 | D38: MUST | E38: Evaluation harness | F38: Measure retrieval, citations, abstention, latency and cost. | G38: Promotion must rely on repeatable evidence, not a demo. | H38: Codex (code) + User (execute) | I38: 1.5 | J38: W3-002 | K38: EVAL-001 | L38: Baseline report and nonzero regression exit behavior exist. | M38: python -m enterprise_ai.evaluation.run --dataset configs/eval/golden.jsonl --out reports/eval.json | N38: Recall@5, citation precision, groundedness, latency and estimated cost recorded. | O38: reports/eval.json | P38: ADR-017 | Q38: W3-04,W3-06 | R38: Restore last approved baseline; block release on unresolved regression. | S38: Not Started | U38: Week 3 Evaluation harness task in the end-to-end architecture. After Code Edit Approval, Codex writes only the approved code/configuration/test code for “Measure retrieval, citations, abstention, latency and cost.”; you run the verification/deployment commands and return the results. Business value: Promotion must rely on repeatable evidence, not a demo. Interview focus: explain where this component sits, how it fails safely and how it is rolled back.
A39: W3-08 | B39: Week 3 | C39: 8 | D39: MUST | E39: Security testing | F39: Test injection, cross-tenant retrieval, unsafe output and logging redaction. | G39: RAG expands the attack surface through untrusted content. | H39: Codex (code) + User (execute) | I39: 1 | J39: W3-003 | K39: SEC-001 | L39: All adversarial fixtures fail safely. | M39: pytest tests/security -q | N39: No unauthorized chunk/action; no raw content in logs. | O39: docs/test-evidence/W3-08-security.txt | P39: ADR-006 | Q39: W3-05 | R39: Disable affected path; purge/re-index poisoned test document. | S39: Not Started | U39: Week 3 Security testing task in the end-to-end architecture. After Code Edit Approval, Codex writes only the approved code/configuration/test code for “Test injection, cross-tenant retrieval, unsafe output and logging redaction.”; you run the verification/deployment commands and return the results. Business value: RAG expands the attack surface through untrusted content. Interview focus: explain where this component sits, how it fails safely and how it is rolled back.
A40: W3-09 | B40: Week 3 | C40: 9 | D40: MUST | E40: Telemetry | F40: Record retrieval/model/token/guardrail metrics without content. | G40: Stage-level data explains latency, errors and cost. | H40: Codex (code) + User (execute) | I40: 0.75 | J40: W4-003 | K40: OBS-001 | L40: Metrics include versions/outcomes and exclude prompt/document text. | M40: pytest tests/unit/test_telemetry.py -q | N40: Redaction tests pass; metrics names are documented. | O40: docs/test-evidence/W3-09-telemetry.txt | P40: ADR-008 | Q40: W3-04 | R40: Disable exporter or revert instrumentation, not core answer path. | S40: Not Started | U40: Week 3 Telemetry task in the end-to-end architecture. After Code Edit Approval, Codex writes only the approved code/configuration/test code for “Record retrieval/model/token/guardrail metrics without content.”; you run the verification/deployment commands and return the results. Business value: Stage-level data explains latency, errors and cost. Interview focus: explain where this component sits, how it fails safely and how it is rolled back.
A41: W3-10 | B41: Week 3 | C41: 10 | D41: MUST | E41: Regression gate | F41: Set initial thresholds: Recall@5 >=0.85 and citation-valid/safe-abstain >=95%. | G41: Thresholds convert evaluation into a release decision. | H41: User (execute) + Codex (guide/code) | I41: 0.75 | J41: W3-002 | K41: SLO-001 | L41: CI-style command fails on a material regression. | M41: make evaluate | N41: Baseline passes; synthetic regression fails. | O41: docs/test-evidence/W3-10-gate.txt | P41: ADR-017 | Q41: W3-07 | R41: Revert candidate prompt/model/index and preserve failing evidence. | S41: Not Started | U41: Week 3 Regression gate task in the end-to-end architecture. After Code Edit Approval, Codex writes only the approved code/configuration/test code for “Set initial thresholds: Recall@5 >=0.85 and citation-valid/safe-abstain >=95%.”; you run the verification/deployment commands and return the results. Business value: Thresholds convert evaluation into a release decision. Interview focus: explain where this component sits, how it fails safely and how it is rolled back.
A42: W3-11 | B42: Week 3 | C42: 11 | D42: MUST | E42: Rollback drill | F42: Restore prior prompt/model/retriever/index configuration and re-evaluate. | G42: RAG changes can regress without application code changes. | H42: User (execute) + Codex (guide/code) | I42: 1 | J42: W3-ROLLBACK-001 | K42: None | L42: Last-known-good configuration returns baseline results. | M42: make rollback-rag && make evaluate | N42: Rollback record identifies versions and post-rollback metrics. | O42: docs/rollback-records/W3-rag.md | P42: ADR-012 | Q42: W3-10 | R42: Forward-fix only after a new feature cycle. | S42: Not Started | U42: Week 3 Rollback drill task in the end-to-end architecture. After Code Edit Approval, Codex writes only the approved code/configuration/test code for “Restore prior prompt/model/retriever/index configuration and re-evaluate.”; you run the verification/deployment commands and return the results. Business value: RAG changes can regress without application code changes. Interview focus: explain where this component sits, how it fails safely and how it is rolled back.
...

Sheet 03 W1 Control Foundation
A1: Week 1 — Control Foundation
A2: Control foundation: repo, traceability, test/security gates, separated Terraform roots and cleanup-verifier skeleton.
A4: Progress | D4: Blocked | G4: Exit gate
A5: =IF(COUNTA(O10:O40)=0,0,COUNTIF(O10:O40,"Done")/COUNTA(A10:A40)) -> 0.52173913 | D5: =COUNTIF(O10:O40,"Blocked") -> 0 | G5: Preflight, tests, reviewed-plan and cleanup workflows are understood and pass before RAG code.
A9: Step ID | B9: Seq | C9: Priority | D9: Workstream | E9: Action | F9: Architecture Reason | G9: Owner | H9: Effort | I9: Prompt | J9: User TODO | K9: Acceptance | L9: Owner Verify | M9: Evidence | N9: Rollback/Teardown | O9: Status | P9: Task Context
A10: W1-01 | B10: 1 | C10: MUST | D10: Scope | E10: Confirm the first use case, user group, exclusions and measurable MVP outcome. | F10: A narrow use case prevents a platform-without-a-problem and sets evaluation truth. | G10: User | H10: 1 | I10: W1-MVP-001 | J10: USE-001, DATA-001, EVAL-001 | K10: One approved one-page scope and 5 representative questions. | L10: Owner review of docs/features/MVP-001.md | M10: docs/features/MVP-001.md | N10: Revert scope file before implementation begins. | O10: Done | P10: Week 1 business/decision documentation task in Scope. The owner provides or approves the facts; after Document Writing Approval, Codex may draft only the approved business-first documentation. No code or command execution is permitted. Business value: A narrow use case prevents a platform-without-a-problem and sets evaluation truth. Interview focus: explain the decision, its alternatives and downstream impact.
A11: W1-02 | B11: 2 | C11: MUST | D11: Governance | E11: Record source precedence: v1.1 controls override older schedule while preserving technical prompts. | F11: Prevents Codex and coach from following conflicting weekly sequences. | G11: User (execute) + Codex (guide/code) | H11: 0.5 | I11: W1-GOV-001 | J11: None | K11: Decision recorded and referenced by all feature prompts. | L11: Review docs/adr/ADR-000-source-precedence.md | M11: docs/adr/ADR-000-source-precedence.md | N11: Restore prior ADR only through reviewed superseding decision. | O11: Done | P11: Week 1 business/decision documentation task in Governance. The owner provides or approves the facts; after Document Writing Approval, Codex may draft only the approved business-first documentation. No code or command execution is permitted. Business value: Prevents Codex and coach from following conflicting weekly sequences. Interview focus: explain the decision, its alternatives and downstream impact.
A12: W1-03 | B12: 3 | C12: MUST | D12: Repository | E12: Create the monorepo and documentation/evidence structure. | F12: Gives every change an auditable home and supports clean ownership. | G12: Codex (code) + User (execute) | H12: 1.5 | I12: W1-001 | J12: TAG-001 | K12: Required folders, README and Makefile exist. | L12: find . -maxdepth 3 -type d | sort | M12: docs/test-evidence/W1-03-layout.txt | N12: Delete only newly created empty skeleton paths after diff review. | O12: Done | P12: Week 1 Repository task in the end-to-end architecture. After Code Edit Approval, Codex writes only the approved code/configuration/test code for “Create the monorepo and documentation/evidence structure.”; you run the verification/deployment commands and return the results. Business value: Gives every change an auditable home and supports clean ownership. Interview focus: explain where this component sits, how it fails safely and how it is rolled back.
A13: W1-04 | B13: 4 | C13: MUST | D13: Traceability | E13: Create feature-matrix.yaml and the first feature record. | F13: Links purpose, files, tests, cost, approval, rollback and teardown. | G13: Codex (code) + User (execute) | H13: 1 | I13: W1-001 | J13: USE-001, TAG-001 | K13: Schema validates and feature MVP-001 is planned. | L13: python tools/validate_feature_matrix.py | M13: docs/test-evidence/W1-04-feature-matrix.json | N13: Restore previous matrix version from Git. | O13: Done | P13: Week 1 Traceability task in the end-to-end architecture. After Code Edit Approval, Codex writes only the approved code/configuration/test code for “Create feature-matrix.yaml and the first feature record.”; you run the verification/deployment commands and return the results. Business value: Links purpose, files, tests, cost, approval, rollback and teardown. Interview focus: explain where this component sits, how it fails safely and how it is rolled back.
A14: W1-05 | B14: 5 | C14: MUST | D14: Python foundation | E14: Create reproducible dependencies and typed configuration. | F14: Fail-fast configuration and portable dependencies reduce hidden runtime risk. | G14: Codex (code) + User (execute) | H14: 1.5 | I14: W1-002 | J14: AWS-002, BED-001, EMB-001 | K14: pip install succeeds; config tests pass offline. | L14: pip install -r requirements.txt && pytest tests/unit/test_config.py -q | M14: docs/test-evidence/W1-05-config.txt | N14: Revert dependency/config commit and recreate virtual environment. | O14: Done | P14: Week 1 Python foundation task in the end-to-end architecture. After Code Edit Approval, Codex writes only the approved code/configuration/test code for “Create reproducible dependencies and typed configuration.”; you run the verification/deployment commands and return the results. Business value: Fail-fast configuration and portable dependencies reduce hidden runtime risk. Interview focus: explain where this component sits, how it fails safely and how it is rolled back.
A15: W1-06 | B15: 6 | C15: MUST | D15: Testing | E15: Create pytest layers, deterministic fakes and evidence capture. | F15: Testing is a feature gate, not an afterthought. | G15: Codex (code) + User (execute) | H15: 1.25 | I15: W1-003 | J15: None | K15: Markers and sample feature test run locally. | L15: pytest tests/unit tests/feature -q | M15: docs/test-evidence/W1-06-tests.json | N15: Revert test framework commit; no platform resources exist. | O15: Done | P15: Week 1 Testing task in the end-to-end architecture. After Code Edit Approval, Codex writes only the approved code/configuration/test code for “Create pytest layers, deterministic fakes and evidence capture.”; you run the verification/deployment commands and return the results. Business value: Testing is a feature gate, not an afterthought. Interview focus: explain where this component sits, how it fails safely and how it is rolled back.
A16: W1-07 | B16: 7 | C16: MUST | D16: Developer controls | E16: Add Make targets for preflight, test, scan, plan, rollback, destroy-plan and verify-clean. | F16: A single, reviewable command vocabulary keeps user and Codex synchronized. | G16: Codex (code) + User (execute) | H16: 1 | I16: W1-001 | J16: None | K16: Make help documents safe commands; mutating commands are gated. | L16: make help && make preflight | M16: docs/test-evidence/W1-07-make.txt | N16: Revert Makefile changes. | O16: Done | P16: Week 1 Developer controls task in the end-to-end architecture. After Code Edit Approval, Codex writes only the approved code/configuration/test code for “Add Make targets for preflight, test, scan, plan, rollback, destroy-plan and verify-clean.”; you run the verification/deployment commands and return the results. Business value: A single, reviewable command vocabulary keeps user and Codex synchronized. Interview focus: explain where this component sits, how it fails safely and how it is rolled back.
A17: W1-08 | B17: 8 | C17: MUST | D17: DevSecOps | E17: Add pre-commit formatting, linting and secret scanning baseline. | F17: Shift-left checks stop secrets and poor-quality changes before PR. | G17: Codex (code) + User (execute) | H17: 1 | I17: W1-003 | J17: SEC-003 | K17: Insecure secret fixture is blocked without committing a real secret. | L17: pre-commit run --all-files | M17: docs/test-evidence/W1-08-precommit.txt | N17: Revert hooks only after owner review; rotate any accidentally exposed credential. | O17: Done | P17: Week 1 DevSecOps task in the end-to-end architecture. After Code Edit Approval, Codex writes only the approved code/configuration/test code for “Add pre-commit formatting, linting and secret scanning baseline.”; you run the verification/deployment commands and return the results. Business value: Shift-left checks stop secrets and poor-quality changes before PR. Interview focus: explain where this component sits, how it fails safely and how it is rolled back.
