Workbook

Sheet 00 Start Here
A1: Enterprise AI Architecture — Owner-Led Learning and Execution Tracker v1.4.0
A2: Objective: learn and own the complete enterprise AI decision flow under FOUR APPROVAL GATES PLUS OWNER TESTING AND WEEKLY LEARNING; Codex writes only inside explicit gates and the owner executes every command.
A4: FOUR APPROVAL GATES PLUS OWNER TESTING AND WEEKLY LEARNING
A5: 1 | B5: Review dashboard and owner inputs | C5: Choose restart or resume later; preserve historical status until you decide. | E5: MUST — required for the six-week MVP and weekly gate.
A6: 2 | B6: Paste CTX-001 and CTRL-001 | C6: Set the architecture context and the code-only/owner-execution boundary. | E6: SHOULD — hardening or AWS deployment value; defer only with owner-recorded risk.
A7: 3 | B7: Gate 1 — paste one Main Prompt | C7: Codex performs complete read-only impact analysis and returns one consolidated plan; no edits or execution. | E7: OPTIONAL — learn/adopt only when a measured requirement justifies cost/complexity.
A8: 4 | B8: Review impact matrix and decide | C8: Confirm business purpose, architecture, all producers/consumers, exact paths, tests, access, cost, rollback, teardown and all owner decisions together. | E8: Codex writes code; the owner runs every test, deployment, rollback, teardown and access-sensitive command.
A9: 5 | B9: Gate 2 — paste Column L approval | C9: Use exact Code Edit Approval, or bounded Content Edit Approval for document/governance tasks. Baseline drift blocks editing. | E9: A failure produces diagnosis and one owner command at a time; source fixes require a new Code Edit Approval.
A10: 6 | B10: Receive bounded changes and owner guide | C10: Codex reports the read-only diff, complete owner execution order and post-implementation learning summary; Codex runs nothing. | E10: Documentation is a separate approved stage and must state business value in clear wording.
A11: 7 | B11: Owner executes TEST-001 | C11: Run one command at a time with cache-safe scopes and stop conditions; failures receive complete impact analysis before one consolidated remediation approval. | E11: Final approval follows owner testing and document review; Codex never self-approves.
A12: 8 | B12: Gate 3 — paste Column M approval | C12: Codex writes only exact approved documentation and returns the complete Column M Approved Document Manifest. | E12: Weekly learning is mandatory before progressing: business story, technical deep-dive, layman analogy and interview teach-back.
A13: 9 | B13: Gate 4 — paste Column N approval | C13: Codex preflights and closes every manifest document, records owner-supplied reviewer/decision/date and returns full reconciliation. | E13: Editable project inputs — owner maintained
A14: 10 | B14: Owner updates tracker; complete weekly learning | C14: Only after complete Column N closure, update Excel yourself and complete the mandatory end-of-week teach-back before progression. | E14: Project start date
E15: Owner | F15: Gyan Prakash Rai
E16: Current week | F16: Week 2
E17: Monthly sandbox budget | F17: TODO
E18: Restart / resume decision | F18: Resume
A19: Source precedence remains unchanged. This version changes execution ownership and learning controls only: Codex writes approved code; the owner tests, deploys, remediates and approves.
A22: W7–W12 EXTENSION — governed data, inference, MLOps, advanced RAG, SRE/DR and automated capstone closure.
A23: W7-001-remediation remains the source-control dependency for new capability. Owner-deferred GAP-01–04 alone do not block an explicitly approved source-only Column L; they remain blocking for dependent live/cloud execution and final readiness/closure. Check each task’s actual prerequisites.
A24: Extend existing Week 1–6 components; do not create duplicate API, agent, RAG, observability, Terraform or deployment paths.
A25: Final operating model: the owner uses repository-derived backend CLI commands to trigger, approve, watch or cancel GitHub Actions and HCP Terraform workflows. The workflows—not ad-hoc Terraform, kubectl or console changes—perform deployment, rollback/recovery and teardown.
A26: Week 12 requires actual owner-approved live deployment, an owner-visible model test, automated rollback/DR with restore or redeployment, automated teardown, native-residue checks and delayed cost closure. Local implementation and TEST-001 remain separate prerequisites, not substitutes.
A27: Each Main Prompt and Column L handoff must explain the task in business, technical and plain language. After implementation, Column L must give exact owner TEST-001 commands grounded in the edited repository; results and documentation remain separate gates.
A28: The owner-managed tracker may stay open for updates, modified by the owner, with an Excel lock present or absent. Codex reports and preserves it, excludes it from source-edit baselines and never treats its open state alone as an implementation blocker or edits it without separate tracker authority.
A29: Initial extension state: remediation Not Started; all later tasks Blocked; all new evidence NOT RUN; production readiness NOT ESTABLISHED.
A30: Tracker edit approval: Gyan Prakash Rai — 10/10/2026 16:39:00 (Asia/Singapore). Scope: W7–W12 tracker extension, layouts and v1.4.0 normalization only; no implementation, deployment, rollback, teardown or cloud-mutation authority.

Sheet 01 Dashboard
A1: Execution Dashboard
A2: All KPIs are formula-driven from tracker sheets. Historical status is preserved; the owner executes tests/deployments and updates source records after final approval.
A4: Total steps | D4: Done | G4: Overall progress | J4: Blocked
A5: =COUNTA('02 Master Plan'!$A$6:$A$120) -> 111 | D5: =COUNTIF('02 Master Plan'!$S$6:$S$120,"Done") -> 80 | G5: =IF(A5=0,0,D5/A5) -> 0.72072072 | J5: =COUNTIF('02 Master Plan'!$S$6:$S$120,"Blocked") -> 30
A7: Open owner TODOs | D7: Tests passed | G7: Decisions approved | J7: Lifecycle tests passed
A8: =COUNTIFS('13 Owner TODOs'!$F$6:$F$80,"<>Done",'13 Owner TODOs'!$A$6:$A$80,"<>") -> 29 | D8: =COUNTIF('11 Test Evidence'!$H$6:$H$80,"Pass")+COUNTIF('11 Test Evidence'!$H$6:$H$80,"PASS") -> 12 | G8: =COUNTIF('12 Decision Log'!$C$6:$C$60,"Baseline Approved")+COUNTIF('12 Decision Log'!$C$6:$C$60,"Approved") -> 18 | J8: =COUNTIFS('11 Test Evidence'!$C$6:$C$80,"Teardown",'11 Test Evidence'!$H$6:$H$80,"Pass")+COUNTIFS('11 Test Evidence'!$C$6:$C$80,"Teardown",'11 Test Evidence'!$H$6:$H$80,"PASS") -> 2
A12: Week | B12: Total | C12: Done | D12: Progress | E12: Blocked | G12: Week | H12: Progress
A13: Week 1 | B13: =COUNTIF('02 Master Plan'!$B$6:$B$120,A13) -> 13 | C13: =COUNTIFS('02 Master Plan'!$B$6:$B$120,A13,'02 Master Plan'!$S$6:$S$120,"Done") -> 13 | D13: =IF(B13=0,0,C13/B13) -> 1 | E13: =COUNTIFS('02 Master Plan'!$B$6:$B$120,A13,'02 Master Plan'!$S$6:$S$120,"Blocked") -> 0 | G13: =A13 -> Week 1 | H13: =D13 -> 1
A14: Week 2 | B14: =COUNTIF('02 Master Plan'!$B$6:$B$120,A14) -> 13 | C14: =COUNTIFS('02 Master Plan'!$B$6:$B$120,A14,'02 Master Plan'!$S$6:$S$120,"Done") -> 13 | D14: =IF(B14=0,0,C14/B14) -> 1 | E14: =COUNTIFS('02 Master Plan'!$B$6:$B$120,A14,'02 Master Plan'!$S$6:$S$120,"Blocked") -> 0 | G14: =A14 -> Week 2 | H14: =D14 -> 1
A15: Week 3 | B15: =COUNTIF('02 Master Plan'!$B$6:$B$120,A15) -> 13 | C15: =COUNTIFS('02 Master Plan'!$B$6:$B$120,A15,'02 Master Plan'!$S$6:$S$120,"Done") -> 13 | D15: =IF(B15=0,0,C15/B15) -> 1 | E15: =COUNTIFS('02 Master Plan'!$B$6:$B$120,A15,'02 Master Plan'!$S$6:$S$120,"Blocked") -> 0 | G15: =A15 -> Week 3 | H15: =D15 -> 1
A16: Week 4 | B16: =COUNTIF('02 Master Plan'!$B$6:$B$120,A16) -> 13 | C16: =COUNTIFS('02 Master Plan'!$B$6:$B$120,A16,'02 Master Plan'!$S$6:$S$120,"Done") -> 13 | D16: =IF(B16=0,0,C16/B16) -> 1 | E16: =COUNTIFS('02 Master Plan'!$B$6:$B$120,A16,'02 Master Plan'!$S$6:$S$120,"Blocked") -> 0 | G16: =A16 -> Week 4 | H16: =D16 -> 1
A17: Week 5 | B17: =COUNTIF('02 Master Plan'!$B$6:$B$120,A17) -> 14 | C17: =COUNTIFS('02 Master Plan'!$B$6:$B$120,A17,'02 Master Plan'!$S$6:$S$120,"Done") -> 14 | D17: =IF(B17=0,0,C17/B17) -> 1 | E17: =COUNTIFS('02 Master Plan'!$B$6:$B$120,A17,'02 Master Plan'!$S$6:$S$120,"Blocked") -> 0 | G17: =A17 -> Week 5 | H17: =D17 -> 1
A18: Week 6 | B18: =COUNTIF('02 Master Plan'!$B$6:$B$120,A18) -> 14 | C18: =COUNTIFS('02 Master Plan'!$B$6:$B$120,A18,'02 Master Plan'!$S$6:$S$120,"Done") -> 14 | D18: =IF(B18=0,0,C18/B18) -> 1 | E18: =COUNTIFS('02 Master Plan'!$B$6:$B$120,A18,'02 Master Plan'!$S$6:$S$120,"Blocked") -> 0 | G18: =A18 -> Week 6 | H18: =D18 -> 1
A21: Weekly gate interpretation
A22: READY: every MUST task is Done, tests have evidence and the owner signs off.
A23: BLOCKED: identify the specific missing task gate; deferred GAP-01–04 alone do not bar separately approved source-only edits, but still bar dependent live/cloud work and closure.
A24: IN PROGRESS: Codex writes approved code only; the owner follows TEST-001 guidance and returns each command result.
A25: Done requires owner-executed validation, approved business-first documentation, rollback/teardown evidence and final owner approval.
A26: Week 12 exit target: configure GitHub and HCP Terraform, enforce HCP OPA policy sets and mandatory run tasks, then actually run owner-triggered automated deployment, visible model testing, rollback/DR recovery and teardown. Final readiness remains NOT ESTABLISHED until the live evidence exists.
A28: W7–W12 Extension Dashboard — evidence-led status; adding work does not inflate completion
A29: Week | B29: Total | C29: Done | D29: Progress | E29: Blocked | G29: Week | H29: Progress
A30: Week 7 | B30: =COUNTIF('02 Master Plan'!$B$6:$B$120,A30) -> 6 | C30: =COUNTIFS('02 Master Plan'!$B$6:$B$120,A30,'02 Master Plan'!$S$6:$S$120,"Done") -> 0 | D30: =IF(B30=0,0,C30/B30) -> 0 | E30: =COUNTIFS('02 Master Plan'!$B$6:$B$120,A30,'02 Master Plan'!$S$6:$S$120,"Blocked") -> 5 | G30: =A30 -> Week 7 | H30: =D30 -> 0
A31: Week 8 | B31: =COUNTIF('02 Master Plan'!$B$6:$B$120,A31) -> 5 | C31: =COUNTIFS('02 Master Plan'!$B$6:$B$120,A31,'02 Master Plan'!$S$6:$S$120,"Done") -> 0 | D31: =IF(B31=0,0,C31/B31) -> 0 | E31: =COUNTIFS('02 Master Plan'!$B$6:$B$120,A31,'02 Master Plan'!$S$6:$S$120,"Blocked") -> 5 | G31: =A31 -> Week 8 | H31: =D31 -> 0
A32: Week 9 | B32: =COUNTIF('02 Master Plan'!$B$6:$B$120,A32) -> 5 | C32: =COUNTIFS('02 Master Plan'!$B$6:$B$120,A32,'02 Master Plan'!$S$6:$S$120,"Done") -> 0 | D32: =IF(B32=0,0,C32/B32) -> 0 | E32: =COUNTIFS('02 Master Plan'!$B$6:$B$120,A32,'02 Master Plan'!$S$6:$S$120,"Blocked") -> 5 | G32: =A32 -> Week 9 | H32: =D32 -> 0
A33: Week 10 | B33: =COUNTIF('02 Master Plan'!$B$6:$B$120,A33) -> 5 | C33: =COUNTIFS('02 Master Plan'!$B$6:$B$120,A33,'02 Master Plan'!$S$6:$S$120,"Done") -> 0 | D33: =IF(B33=0,0,C33/B33) -> 0 | E33: =COUNTIFS('02 Master Plan'!$B$6:$B$120,A33,'02 Master Plan'!$S$6:$S$120,"Blocked") -> 5 | G33: =A33 -> Week 10 | H33: =D33 -> 0
A34: Week 11 | B34: =COUNTIF('02 Master Plan'!$B$6:$B$120,A34) -> 5 | C34: =COUNTIFS('02 Master Plan'!$B$6:$B$120,A34,'02 Master Plan'!$S$6:$S$120,"Done") -> 0 | D34: =IF(B34=0,0,C34/B34) -> 0 | E34: =COUNTIFS('02 Master Plan'!$B$6:$B$120,A34,'02 Master Plan'!$S$6:$S$120,"Blocked") -> 5 | G34: =A34 -> Week 11 | H34: =D34 -> 0
A35: Week 12 | B35: =COUNTIF('02 Master Plan'!$B$6:$B$120,A35) -> 5 | C35: =COUNTIFS('02 Master Plan'!$B$6:$B$120,A35,'02 Master Plan'!$S$6:$S$120,"Done") -> 0 | D35: =IF(B35=0,0,C35/B35) -> 0 | E35: =COUNTIFS('02 Master Plan'!$B$6:$B$120,A35,'02 Master Plan'!$S$6:$S$120,"Blocked") -> 5 | G35: =A35 -> Week 12 | H35: =D35 -> 0
A37: Extension readiness and evidence gates
A38: W7 remediation | B38: =IFERROR(INDEX('02 Master Plan'!$S$6:$S$120,MATCH("W7-001-remediation",'02 Master Plan'!$A$6:$A$120,0)),"MISSING") -> Not Started | D38: W6 carry-forward/P0 | E38: =IF(B38="Done","SOURCE PACKAGE DONE; P0 DEFERRED","OPEN") -> OPEN
A39: Data platform readiness | B39: =IF(COUNTIFS('02 Master Plan'!$B$6:$B$120,"Week 7",'02 Master Plan'!$S$6:$S$120,"<>Done")=0,"READY","BLOCKED") -> BLOCKED | D39: Production inference | E39: =IF(COUNTIFS('02 Master Plan'!$B$6:$B$120,"Week 8",'02 Master Plan'!$S$6:$S$120,"<>Done")=0,"READY","BLOCKED") -> BLOCKED
A40: MLOps promotion | B40: =IF(COUNTIFS('02 Master Plan'!$B$6:$B$120,"Week 9",'02 Master Plan'!$S$6:$S$120,"<>Done")=0,"READY","BLOCKED") -> BLOCKED | D40: Advanced RAG/evaluation | E40: =IF(COUNTIFS('02 Master Plan'!$B$6:$B$120,"Week 10",'02 Master Plan'!$S$6:$S$120,"<>Done")=0,"READY","BLOCKED") -> BLOCKED
A41: SRE/DR readiness | B41: =IF(COUNTIFS('02 Master Plan'!$B$6:$B$120,"Week 11",'02 Master Plan'!$S$6:$S$120,"<>Done")=0,"READY","BLOCKED") -> BLOCKED | D41: Automated lifecycle | E41: =IF(COUNTIFS('02 Master Plan'!$B$6:$B$120,"Week 12",'02 Master Plan'!$S$6:$S$120,"<>Done")=0,"READY","BLOCKED") -> BLOCKED
A42: Evidence gate progress | B42: =COUNTIF('11 Test Evidence'!$H$40:$H$70,"PASS")/COUNTA('11 Test Evidence'!$A$40:$A$70) -> 0 | D42: Cost/KMS closure | E42: =IF(B38="Done","CLOSED","INDETERMINATE") -> INDETERMINATE
A43: Status and final-readiness interpretation
A44: Done | B44: =COUNTIF('02 Master Plan'!$S$86:$S$116,"Done") -> 0 | D44: Production readiness | E44: =IF(AND(COUNTIFS('02 Master Plan'!$B$86:$B$116,"Week 12",'02 Master Plan'!$S$86:$S$116,"<>Done")=0,COUNTIF('11 Test Evidence'!$H$40:$H$70,"<>PASS")=0),"ESTABLISHED — OWNER APPROVAL REQUIRED","NOT ESTABLISHED") -> NOT ESTABLISHED
A45: In Progress | B45: =COUNTIF('02 Master Plan'!$S$86:$S$116,"In Progress") -> 0
A46: Blocked | B46: =COUNTIF('02 Master Plan'!$S$86:$S$116,"Blocked") -> 30
A47: Not Started | B47: =COUNTIF('02 Master Plan'!$S$86:$S$116,"Not Started") -> 1
A48: INDETERMINATE evidence | B48: =COUNTIF('11 Test Evidence'!$H$40:$H$70,"INDETERMINATE") -> 0
A49: Weekly learning done | B49: =COUNTIFS('02 Master Plan'!$A$86:$A$116,"*LEARN*",'02 Master Plan'!$S$86:$S$116,"Done") -> 0

Sheet 02 Master Plan
A1: Master Twelve-Week Owner-Led Learning Plan — v1.4.0
A2: Historical statuses, evidence, notes and dates are preserved. Prompt execution follows FOUR APPROVAL GATES PLUS OWNER TESTING AND WEEKLY LEARNING; complete-impact review precedes any bounded edit, and only the owner updates tracker progress.
A5: Step ID | B5: Week | C5: Seq | D5: Priority | E5: Workstream | F5: Task / Outcome | G5: Why It Matters | H5: Owner | I5: Effort (h) | J5: Prompt ID | K5: User TODO IDs | L5: Acceptance Criteria | M5: Owner Verification Command | N5: Expected Result | O5: Evidence Path | P5: Decision ID | Q5: Dependency | R5: Rollback / Teardown | S5: Status | T5: Notes | U5: Task Context
A6: W1-01 | B6: Week 1 | C6: 1 | D6: MUST | E6: Scope | F6: Confirm the first use case, user group, exclusions and measurable MVP outcome. | G6: A narrow use case prevents a platform-without-a-problem and sets evaluation truth. | H6: User | I6: 1 | J6: W1-MVP-001 | K6: USE-001, DATA-001, EVAL-001 | L6: One approved one-page scope and 5 representative questions. | M6: Owner review of docs/features/MVP-001.md | N6: Scope, exclusions and success measures approved. | O6: docs/features/MVP-001.md | P6: ADR-001 | Q6: None | R6: Revert scope file before implementation begins. | S6: Done | T6: Use W1-MVP-001. Approve five starter questions now; the full 25+ golden dataset is completed under W3-002 in Week 3. | Implementation commit 210381c3ddbc9aab83ccaeb11a59db8d8dad549b; owner approval date 2026-08-18; owner reaffirmed 2026-08-18T16:01:18Z. | U6: Week 1 business/decision documentation task in Scope. The owner provides or approves the facts; after Document Writing Approval, Codex may draft only the approved business-first documentation. No code or command execution is permitted. Business value: A narrow use case prevents a platform-without-a-problem and sets evaluation truth. Interview focus: explain the decision, its alternatives and downstream impact.
A7: W1-02 | B7: Week 1 | C7: 2 | D7: MUST | E7: Governance | F7: Record source precedence: v1.1 controls override older schedule while preserving technical prompts. | G7: Prevents Codex and coach from following conflicting weekly sequences. | H7: User (execute) + Codex (guide/code) | I7: 0.5 | J7: W1-GOV-001 | K7: None | L7: Decision recorded and referenced by all feature prompts. | M7: Review docs/adr/ADR-000-source-precedence.md | N7: v1.1 is named implementation authority. | O7: docs/adr/ADR-000-source-precedence.md | P7: ADR-016 | Q7: W1-01 | R7: Restore prior ADR only through reviewed superseding decision. | S7: Done | T7: Use W1-GOV-001. Create ADR-000 only; docs/codex files are not prerequisites for this task. | Implementation commit 210381c3ddbc9aab83ccaeb11a59db8d8dad549b; owner approval date 2026-08-18; owner reaffirmed 2026-08-18T16:01:18Z. | U7: Week 1 business/decision documentation task in Governance. The owner provides or approves the facts; after Document Writing Approval, Codex may draft only the approved business-first documentation. No code or command execution is permitted. Business value: Prevents Codex and coach from following conflicting weekly sequences. Interview focus: explain the decision, its alternatives and downstream impact.
A8: W1-03 | B8: Week 1 | C8: 3 | D8: MUST | E8: Repository | F8: Create the monorepo and documentation/evidence structure. | G8: Gives every change an auditable home and supports clean ownership. | H8: Codex (code) + User (execute) | I8: 1.5 | J8: W1-001 | K8: TAG-001 | L8: Required folders, README and Makefile exist. | M8: find . -maxdepth 3 -type d | sort | N8: Layout matches blueprint; no unrelated files changed. | O8: docs/test-evidence/W1-03-layout.txt | P8: ADR-016 | Q8: W1-02 | R8: Delete only newly created empty skeleton paths after diff review. | S8: Done | T8: Implementation commit 210381c3ddbc9aab83ccaeb11a59db8d8dad549b; owner approval date 2026-08-18; owner reaffirmed 2026-08-18T16:01:18Z. | U8: Week 1 Repository task in the end-to-end architecture. After Code Edit Approval, Codex writes only the approved code/configuration/test code for “Create the monorepo and documentation/evidence structure.”; you run the verification/deployment commands and return the results. Business value: Gives every change an auditable home and supports clean ownership. Interview focus: explain where this component sits, how it fails safely and how it is rolled back.
A9: W1-04 | B9: Week 1 | C9: 4 | D9: MUST | E9: Traceability | F9: Create feature-matrix.yaml and the first feature record. | G9: Links purpose, files, tests, cost, approval, rollback and teardown. | H9: Codex (code) + User (execute) | I9: 1 | J9: W1-001 | K9: USE-001, TAG-001 | L9: Schema validates and feature MVP-001 is planned. | M9: python -m tools.platformctl validate | N9: Validation exits 0; missing required fields fail. | O9: docs/test-evidence/W1-04-feature-matrix.json | P9: ADR-016 | Q9: W1-03 | R9: Restore previous matrix version from Git. | S9: Done | T9: Implementation commit 210381c3ddbc9aab83ccaeb11a59db8d8dad549b; owner approval date 2026-08-18; owner reaffirmed 2026-08-18T16:01:18Z. | U9: Week 1 Traceability task in the end-to-end architecture. After Code Edit Approval, Codex writes only the approved code/configuration/test code for “Create feature-matrix.yaml and the first feature record.”; you run the verification/deployment commands and return the results. Business value: Links purpose, files, tests, cost, approval, rollback and teardown. Interview focus: explain where this component sits, how it fails safely and how it is rolled back.
A10: W1-05 | B10: Week 1 | C10: 5 | D10: MUST | E10: Python foundation | F10: Create reproducible dependencies and typed configuration. | G10: Fail-fast configuration and portable dependencies reduce hidden runtime risk. | H10: Codex (code) + User (execute) | I10: 1.5 | J10: W1-002 | K10: AWS-002, BED-001, EMB-001 | L10: pip install succeeds; config tests pass offline. | M10: TEST-001 — ORDERED OWNER EXECUTION (GUIDANCE; NOT A RUNNABLE BATCH) Codex derives each exact command from the current repository-configured scope, explains purpose, expected result, access/cost/privacy/risk and stop condition, and waits for complete owner output before issuing the next command. Retain this task-specific check order: 1. pip install -r requirements.txt 2. pytest tests/unit/test_config.py -q On FAIL or INDETERMINATE: stop; perform a complete read-only root-cause, producer-consumer and approval-gate audit; request one consolidated remediation approval; never self-remediate. After successful checks, rollback/teardown and zero-residue verification are separate owner commands, also issued one at a time. | N10: No paid/network dependency in unit tests; TODOs remain non-secret. | O10: docs/test-evidence/W1-05-config.txt | P10: ADR-002 | Q10: W1-03 | R10: Revert dependency/config commit and recreate virtual environment. | S10: Done | T10: Implementation commit 210381c3ddbc9aab83ccaeb11a59db8d8dad549b; owner approval date 2026-08-18; owner reaffirmed 2026-08-18T16:01:18Z. | U10: Week 1 Python foundation task in the end-to-end architecture. After Code Edit Approval, Codex writes only the approved code/configuration/test code for “Create reproducible dependencies and typed configuration.”; you run the verification/deployment commands and return the results. Business value: Fail-fast configuration and portable dependencies reduce hidden runtime risk. Interview focus: explain where this component sits, how it fails safely and how it is rolled back.
A11: W1-06 | B11: Week 1 | C11: 6 | D11: MUST | E11: Testing | F11: Create pytest layers, deterministic fakes and evidence capture. | G11: Testing is a feature gate, not an afterthought. | H11: Codex (code) + User (execute) | I11: 1.25 | J11: W1-003 | K11: None | L11: Markers and sample feature test run locally. | M11: pytest tests/unit tests/feature -q | N11: Tests pass; evidence metadata excludes secrets/content. | O11: docs/test-evidence/W1-06-tests.json | P11: ADR-017 | Q11: W1-04,W1-05 | R11: Revert test framework commit; no platform resources exist. | S11: Done | T11: Implementation commit 210381c3ddbc9aab83ccaeb11a59db8d8dad549b; owner approval date 2026-08-18; owner reaffirmed 2026-08-18T16:01:18Z. | U11: Week 1 Testing task in the end-to-end architecture. After Code Edit Approval, Codex writes only the approved code/configuration/test code for “Create pytest layers, deterministic fakes and evidence capture.”; you run the verification/deployment commands and return the results. Business value: Testing is a feature gate, not an afterthought. Interview focus: explain where this component sits, how it fails safely and how it is rolled back.
A12: W1-07 | B12: Week 1 | C12: 7 | D12: MUST | E12: Developer controls | F12: Add Make targets for preflight, test, scan, plan, rollback, destroy-plan and verify-clean. | G12: A single, reviewable command vocabulary keeps user and Codex synchronized. | H12: Codex (code) + User (execute) | I12: 1 | J12: W1-001 | K12: None | L12: Make help documents safe commands; mutating commands are gated. | M12: TEST-001 — ORDERED OWNER EXECUTION (GUIDANCE; NOT A RUNNABLE BATCH) Codex derives each exact command from the current repository-configured scope, explains purpose, expected result, access/cost/privacy/risk and stop condition, and waits for complete owner output before issuing the next command. Retain this task-specific check order: 1. make help 2. make preflight On FAIL or INDETERMINATE: stop; perform a complete read-only root-cause, producer-consumer and approval-gate audit; request one consolidated remediation approval; never self-remediate. After successful checks, rollback/teardown and zero-residue verification are separate owner commands, also issued one at a time. | N12: Preflight passes; apply/destroy are never default dependencies. | O12: docs/test-evidence/W1-07-make.txt | P12: ADR-010, ADR-011 | Q12: W1-03 | R12: Revert Makefile changes. | S12: Done | T12: Implementation commit 210381c3ddbc9aab83ccaeb11a59db8d8dad549b; owner approval date 2026-08-18; owner reaffirmed 2026-08-18T16:01:18Z. | U12: Week 1 Developer controls task in the end-to-end architecture. After Code Edit Approval, Codex writes only the approved code/configuration/test code for “Add Make targets for preflight, test, scan, plan, rollback, destroy-plan and verify-clean.”; you run the verification/deployment commands and return the results. Business value: A single, reviewable command vocabulary keeps user and Codex synchronized. Interview focus: explain where this component sits, how it fails safely and how it is rolled back.
A13: W1-08 | B13: Week 1 | C13: 8 | D13: MUST | E13: DevSecOps | F13: Add pre-commit formatting, linting and secret scanning baseline. | G13: Shift-left checks stop secrets and poor-quality changes before PR. | H13: Codex (code) + User (execute) | I13: 1 | J13: W1-003 | K13: SEC-003 | L13: Insecure secret fixture is blocked without committing a real secret. | M13: pre-commit run --all-files | N13: All checks pass on source; synthetic fixture produces expected failure. | O13: docs/test-evidence/W1-08-precommit.txt | P13: ADR-017 | Q13: W1-05 | R13: Revert hooks only after owner review; rotate any accidentally exposed credential. | S13: Done | T13: Implementation commit 210381c3ddbc9aab83ccaeb11a59db8d8dad549b; owner approval date 2026-08-18; owner reaffirmed 2026-08-18T16:01:18Z. | U13: Week 1 DevSecOps task in the end-to-end architecture. After Code Edit Approval, Codex writes only the approved code/configuration/test code for “Add pre-commit formatting, linting and secret scanning baseline.”; you run the verification/deployment commands and return the results. Business value: Shift-left checks stop secrets and poor-quality changes before PR. Interview focus: explain where this component sits, how it fails safely and how it is rolled back.
A14: W1-09 | B14: Week 1 | C14: 9 | D14: MUST | E14: Terraform lifecycle | F14: Separate infra/bootstrap from infra/environments/sandbox and document state removal last. | G14: A platform cannot fully disappear if its state backend is embedded in the same lifecycle. | H14: Codex (code) + User (execute) | I14: 1.25 | J14: W1-004 | K14: AWS-001, AWS-002, TAG-001 | L14: Two roots validate as skeletons and dependency order is documented. | M14: TEST-001 — ORDERED OWNER EXECUTION (GUIDANCE; NOT A RUNNABLE BATCH) Codex derives each exact command from the current repository-configured scope, explains purpose, expected result, access/cost/privacy/risk and stop condition, and waits for complete owner output before issuing the next command. Retain this task-specific check order: 1. terraform -chdir=infra/bootstrap fmt -check 2. terraform -chdir=infra/environments/sandbox fmt -check On FAIL or INDETERMINATE: stop; perform a complete read-only root-cause, producer-consumer and approval-gate audit; request one consolidated remediation approval; never self-remediate. After successful checks, rollback/teardown and zero-residue verification are separate owner commands, also issued one at a time. | N14: No resource apply; backend/platform boundaries are explicit. | O14: docs/test-evidence/W1-09-roots.txt | P14: ADR-009 | Q14: W1-03 | R14: Revert Terraform skeleton; no state exists yet. | S14: Done | T14: Implementation commit 210381c3ddbc9aab83ccaeb11a59db8d8dad549b; owner approval date 2026-08-18; owner reaffirmed 2026-08-18T16:01:18Z. | W1-004 historical disclosure preserved: commit d3e5ad182fac38dbf166c6ce15b8ade8868379da contained 34 intended paths plus 1 owner workbook path; consolidated commit 210381c3ddbc9aab83ccaeb11a59db8d8dad549b excludes the workbook. | U14: Week 1 Terraform lifecycle task in the end-to-end architecture. After Code Edit Approval, Codex writes only the approved code/configuration/test code for “Separate infra/bootstrap from infra/environments/sandbox and document state removal last.”; you run the verification/deployment commands and return the results. Business value: A platform cannot fully disappear if its state backend is embedded in the same lifecycle. Interview focus: explain where this component sits, how it fails safely and how it is rolled back.
A15: W1-10 | B15: Week 1 | C15: 10 | D15: MUST | E15: Reversibility | F15: Create platformctl command contracts with dry-run and approvals. | G15: Deploy, rollback and teardown need distinct safe semantics. | H15: Codex (code) + User (execute) | I15: 1.5 | J15: W1-004 | K15: DEST-001, KMS-001 | L15: CLI help and unit tests prove confirmation/approval gates. | M15: TEST-001 — ORDERED OWNER EXECUTION (GUIDANCE; NOT A RUNNABLE BATCH) Codex derives each exact command from the current repository-configured scope, explains purpose, expected result, access/cost/privacy/risk and stop condition, and waits for complete owner output before issuing the next command. Retain this task-specific check order: 1. python -m tools.platformctl --help 2. pytest tests/unit/test_platformctl.py -q On FAIL or INDETERMINATE: stop; perform a complete read-only root-cause, producer-consumer and approval-gate audit; request one consolidated remediation approval; never self-remediate. After successful checks, rollback/teardown and zero-residue verification are separate owner commands, also issued one at a time. | N15: No command mutates by default; missing approval fails closed. | O15: docs/test-evidence/W1-10-platformctl.txt | P15: ADR-010, ADR-011, ADR-012 | Q15: W1-09 | R15: Revert CLI commit; no cloud mutation is allowed. | S15: Done | T15: Implementation commit 210381c3ddbc9aab83ccaeb11a59db8d8dad549b; owner approval date 2026-08-18; owner reaffirmed 2026-08-18T16:01:18Z. | W1-004 historical disclosure preserved: commit d3e5ad182fac38dbf166c6ce15b8ade8868379da contained 34 intended paths plus 1 owner workbook path; consolidated commit 210381c3ddbc9aab83ccaeb11a59db8d8dad549b excludes the workbook. | U15: Week 1 Reversibility task in the end-to-end architecture. After Code Edit Approval, Codex writes only the approved code/configuration/test code for “Create platformctl command contracts with dry-run and approvals.”; you run the verification/deployment commands and return the results. Business value: Deploy, rollback and teardown need distinct safe semantics. Interview focus: explain where this component sits, how it fails safely and how it is rolled back.
A16: W1-11 | B16: Week 1 | C16: 11 | D16: MUST | E16: Cleanup verification | F16: Implement mocked tag and service-specific residual checks. | G16: Tag-only discovery misses some resources; native checks close the gap. | H16: Codex (code) + User (execute) | I16: 1 | J16: W1-004 | K16: TAG-001, KMS-001 | L16: Mock orphan makes verify-clean fail; PendingDeletion key is documented exception. | M16: pytest tests/teardown -q | N16: Expected pass/fail matrix is recorded. | O16: docs/test-evidence/W1-11-cleanup.json | P16: ADR-013, ADR-014 | Q16: W1-10 | R16: Revert verifier implementation; keep the control requirement. | S16: Done | T16: Implementation commit 210381c3ddbc9aab83ccaeb11a59db8d8dad549b; owner approval date 2026-08-18; owner reaffirmed 2026-08-18T16:01:18Z. | W1-004 historical disclosure preserved: commit d3e5ad182fac38dbf166c6ce15b8ade8868379da contained 34 intended paths plus 1 owner workbook path; consolidated commit 210381c3ddbc9aab83ccaeb11a59db8d8dad549b excludes the workbook. | U16: Week 1 Cleanup verification task in the end-to-end architecture. After Code Edit Approval, Codex writes only the approved code/configuration/test code for “Implement mocked tag and service-specific residual checks.”; you run the verification/deployment commands and return the results. Business value: Tag-only discovery misses some resources; native checks close the gap. Interview focus: explain where this component sits, how it fails safely and how it is rolled back.
A17: W1-12 | B17: Week 1 | C17: 12 | D17: MUST | E17: Checkpoint | F17: Review diffs, architecture decisions, test evidence and Week 2 readiness. | G17: Owner approval is the stop point between features/weeks. | H17: User | I17: 1 | J17: W1-REVIEW-001 | K17: All Week 1 TODOs | L17: Every MUST step is Done; no blocker or unapproved scope remains. | M17: TEST-001 — ORDERED OWNER EXECUTION (GUIDANCE; NOT A RUNNABLE BATCH) Codex derives each exact command from the current repository-configured scope, explains purpose, expected result, access/cost/privacy/risk and stop condition, and waits for complete owner output before issuing the next command. Retain this task-specific check order: 1. make preflight 2. make test On FAIL or INDETERMINATE: stop; perform a complete read-only root-cause, producer-consumer and approval-gate audit; request one consolidated remediation approval; never self-remediate. After successful checks, rollback/teardown and zero-residue verification are separate owner commands, also issued one at a time. | N17: Owner sign-off recorded with outstanding items explicitly deferred. | O17: docs/deployment-records/W1-signoff.md | P17: ADR-016 | Q17: W1-01:W1-11 | R17: No Week 2 prompt is used until gaps are resolved. | S17: Done | T17: W1-12 readiness PASS; final Week 1 sign-off APPROVED by Gyan Prakash Rai at 2026-08-19T00:10:55+08:00 (Asia/Singapore); sign-off evidence docs/deployment-records/W1-signoff.md; implementation commit 10f03a483f2ff639081c5b57dacaf282a31aaad4. | U17: Week 1 business/decision documentation task in Checkpoint. The owner provides or approves the facts; after Document Writing Approval, Codex may draft only the approved business-first documentation. No code or command execution is permitted. Business value: Owner approval is the stop point between features/weeks. Interview focus: explain the decision, its alternatives and downstream impact.
A18: W1-13 | B18: Week 1 | C18: 13 | D18: MUST | E18: Weekly learning | F18: Complete the Week 1 business, architecture and interview teach-back. | G18: Turns governance, repository, test and lifecycle controls into an explainable architecture story. | H18: User (execute) + Codex (guide/code) | I18: 1 | J18: WEEKLY-LEARN-001 | K18: None | L18: Owner explains the Week 1 business outcome, control flow, decisions, failure boundaries and three interview answers without reading code. | M18: Owner completes the teach-back and records notes in docs/learning/W1-learning-review.md | N18: Business summary, technical deep-dive, layman analogy, decision recap and interview Q&A completed. | O18: docs/learning/W1-learning-review.md | P18: Existing Week 1 ADRs | Q18: W1-12 | R18: No runtime rollback; revise the learning note through document approval if inaccurate. | S18: Done | T18: Added in v1.3.0; historical Week 1 completion records remain unchanged. | U18: Week 1 learning gate after all implementation and checkpoint work. Codex teaches the business outcome and architecture; the owner completes a teach-back and interview practice. No runtime action is permitted. Business value: converts completed work into reusable understanding and decision ownership.
A19: W2-01 | B19: Week 2 | C19: 1 | D19: MUST | E19: Data contracts | F19: Implement provider-neutral document, chunk, query, answer and citation models. | G19: Stable domain types make vector and LLM backends replaceable. | H19: Codex (code) + User (execute) | I19: 1 | J19: W2-001 | K19: DATA-002, SEC-001 | L19: Models validate required identity/classification metadata. | M19: pytest tests/unit/test_models.py -q | N19: Invalid tenant/classification input fails. | O19: docs/test-evidence/W2-01-models.txt | P19: ADR-002 | Q19: W1-13 | R19: Revert model commit; no stored vectors affected. | S19: Done | U19: Week 2 Data contracts task in the end-to-end architecture. After Code Edit Approval, Codex writes only the approved code/configuration/test code for “Implement provider-neutral document, chunk, query, answer and citation models.”; you run the verification/deployment commands and return the results. Business value: Stable domain types make vector and LLM backends replaceable. Interview focus: explain where this component sits, how it fails safely and how it is rolled back.
A20: W2-02 | B20: Week 2 | C20: 2 | D20: MUST | E20: Vector interface | F20: Define VectorStore protocol and in-memory fake with contract tests. | G20: Business logic must not depend on Qdrant/OpenSearch SDK objects. | H20: Codex (code) + User (execute) | I20: 1.25 | J20: W2-001 | K20: None | L20: Fake passes all contract tests. | M20: pytest tests/contract/test_vector_store.py -q | N20: Protocol behavior and normalized errors are stable. | O20: docs/test-evidence/W2-02-vector-contract.txt | P20: ADR-002, ADR-003 | Q20: W2-01 | R20: Revert interface only before downstream adapters merge. | S20: Done | U20: Week 2 Vector interface task in the end-to-end architecture. After Code Edit Approval, Codex writes only the approved code/configuration/test code for “Define VectorStore protocol and in-memory fake with contract tests.”; you run the verification/deployment commands and return the results. Business value: Business logic must not depend on Qdrant/OpenSearch SDK objects. Interview focus: explain where this component sits, how it fails safely and how it is rolled back.
A21: W2-03 | B21: Week 2 | C21: 3 | D21: MUST | E21: Local platform | F21: Start pinned Qdrant through Docker Compose with healthcheck. | G21: A real client/server vector store gives useful local integration evidence. | H21: Codex (code) + User (execute) | I21: 1 | J21: W2-001 | K21: None | L21: Qdrant becomes healthy without an embedded credential. | M21: TEST-001 — QDRANT INTERNAL-ONLY OWNER SEQUENCE (GUIDANCE; NOT A RUNNABLE BATCH) Codex issues one exact command at a time and waits for complete owner output after every step. 1. Validate current Compose configuration: qdrant and the one-shot runner reference only logical qdrant_internal; qdrant_internal retains internal: true; Qdrant has no published host port. 2. Verify approved immutable image identity and Linux/AMD64 constraints without changing resources. 3. Build the approved least-privilege one-shot runner only after separate owner authorization. 4. Start only Qdrant and wait for health on the internal Compose network. 5. Confirm HostConfig.PortBindings is empty and NetworkSettings.Ports contains no host bindings. 6. Run the one-shot internal runner against http://qdrant:6333; it waits for health, tests the bounded collection and deletes that collection in finally. 7. Confirm successful runner exit and no runner container or test collection. 8. Tear down the owner-selected project, volume, internal network, local runner image and orphans through separately issued commands. 9. Verify zero project-labelled container, volume, network and local-image residue. Stop on host publication, non-internal networking, digest/platform mismatch, health failure, unexpected collection, cleanup failure or indeterminate output. | N21: Service is healthy; image version is pinned. | O21: docs/test-evidence/W2-03-qdrant.txt | P21: ADR-003 | Q21: W1-12 | R21: TEST-001 — QDRANT INTERNAL-ONLY ROLLBACK/TEARDOWN (GUIDANCE; NOT A RUNNABLE BATCH) Codex issues exactly one owner command at a time and waits for complete output. 1. Stop and remove the owner-selected Compose project containers and orphans. 2. Remove the project volume and logical qdrant_internal network. 3. Remove only the task-local runner image when approved; do not infer removal of shared immutable base images. 4. Verify zero project-labelled container, volume, network and local-image residue. Stop if any target is ambiguous, outside the approved project, intentionally retained or unverifiable. Qdrant has no host-port publication to remove. | S21: Done | U21: Week 2 Local platform task in the end-to-end architecture. After Code Edit Approval, Codex writes only the approved code/configuration/test code for “Start pinned Qdrant through Docker Compose with healthcheck.”; you run the verification/deployment commands and return the results. Business value: A real client/server vector store gives useful local integration evidence. Interview focus: explain where this component sits, how it fails safely and how it is rolled back.
A22: W2-04 | B22: Week 2 | C22: 4 | D22: MUST | E22: Vector adapters | F22: Implement Qdrant adapter and OpenSearch adapter boundary. | G22: Local and AWS retrieval must satisfy the same contract. | H22: Codex (code) + User (execute) | I22: 1.5 | J22: W2-001 | K22: AWS-002, NET-001 | L22: Fake/Qdrant tests pass; AWS tests remain marked/skipped. | M22: TEST-001 — QDRANT INTERNAL-ONLY OWNER SEQUENCE (GUIDANCE; NOT A RUNNABLE BATCH) Codex issues one exact command at a time and waits for complete owner output after every step. 1. Validate current Compose configuration: qdrant and the one-shot runner reference only logical qdrant_internal; qdrant_internal retains internal: true; Qdrant has no published host port. 2. Verify approved immutable image identity and Linux/AMD64 constraints without changing resources. 3. Build the approved least-privilege one-shot runner only after separate owner authorization. 4. Start only Qdrant and wait for health on the internal Compose network. 5. Confirm HostConfig.PortBindings is empty and NetworkSettings.Ports contains no host bindings. 6. Run the one-shot internal runner against http://qdrant:6333; it waits for health, tests the bounded collection and deletes that collection in finally. 7. Confirm successful runner exit and no runner container or test collection. 8. Tear down the owner-selected project, volume, internal network, local runner image and orphans through separately issued commands. 9. Verify zero project-labelled container, volume, network and local-image residue. Stop on host publication, non-internal networking, digest/platform mismatch, health failure, unexpected collection, cleanup failure or indeterminate output. | N22: No vendor object leaks; timeouts and filters are applied. | O22: docs/test-evidence/W2-04-adapters.txt | P22: ADR-003 | Q22: W2-02,W2-03 | R22: Delete test collection and restore previous adapter version. | S22: Done | U22: Week 2 Vector adapters task in the end-to-end architecture. After Code Edit Approval, Codex writes only the approved code/configuration/test code for “Implement Qdrant adapter and OpenSearch adapter boundary.”; you run the verification/deployment commands and return the results. Business value: Local and AWS retrieval must satisfy the same contract. Interview focus: explain where this component sits, how it fails safely and how it is rolled back.
A23: W2-05 | B23: Week 2 | C23: 5 | D23: MUST | E23: Embeddings | F23: Implement sentence-transformer and deterministic fake embedders. | G23: Local CPU embeddings avoid a paid dependency while preserving provider exit. | H23: Codex (code) + User (execute) | I23: 1.25 | J23: W2-002 | K23: EMB-001 | L23: Batch, normalization and dimension mismatch tests pass. | M23: pytest tests/unit/test_embedder.py -q | N23: Unit tests make no model download; integration model is explicit. | O23: docs/test-evidence/W2-05-embedder.txt | P23: ADR-002 | Q23: W2-01 | R23: Restore previous model configuration and recreate collection if dimension changed. | S23: Done | U23: Week 2 Embeddings task in the end-to-end architecture. After Code Edit Approval, Codex writes only the approved code/configuration/test code for “Implement sentence-transformer and deterministic fake embedders.”; you run the verification/deployment commands and return the results. Business value: Local CPU embeddings avoid a paid dependency while preserving provider exit. Interview focus: explain where this component sits, how it fails safely and how it is rolled back.
A24: W2-06 | B24: Week 2 | C24: 6 | D24: MUST | E24: Ingestion | F24: Implement validation, hashing, normalization and deterministic token chunking. | G24: Reproducible chunk IDs/versioning make re-index and deletion safe. | H24: Codex (code) + User (execute) | I24: 1.5 | J24: W2-003 | K24: DATA-001, DATA-002 | L24: Same input produces same IDs; changed version is distinguishable. | M24: pytest tests/unit/test_chunking.py tests/unit/test_ingestion.py -q | N24: Size/type failures quarantine; no raw content in logs. | O24: docs/test-evidence/W2-06-ingestion.txt | P24: ADR-017 | Q24: W2-01,W2-05 | R24: Delete affected document version and re-ingest last approved manifest. | S24: Done | U24: Week 2 Ingestion task in the end-to-end architecture. After Code Edit Approval, Codex writes only the approved code/configuration/test code for “Implement validation, hashing, normalization and deterministic token chunking.”; you run the verification/deployment commands and return the results. Business value: Reproducible chunk IDs/versioning make re-index and deletion safe. Interview focus: explain where this component sits, how it fails safely and how it is rolled back.
A25: W2-07 | B25: Week 2 | C25: 7 | D25: MUST | E25: Privacy | F25: Add replaceable Presidio PII detection/redaction hook. | G25: PII handling belongs before indexing and telemetry. | H25: Codex (code) + User (execute) | I25: 1 | J25: W2-003 | K25: DATA-003 | L25: Configured PII is redacted/quarantined and never appears in evidence logs. | M25: pytest tests/security/test_pii.py -q | N25: Synthetic PII fixture is handled as policy states. | O25: docs/test-evidence/W2-07-pii.txt | P25: ADR-006 | Q25: W2-06 | R25: Delete derived chunks; restore approved unredacted source only in controlled location. | S25: Done | U25: Week 2 Privacy task in the end-to-end architecture. After Code Edit Approval, Codex writes only the approved code/configuration/test code for “Add replaceable Presidio PII detection/redaction hook.”; you run the verification/deployment commands and return the results. Business value: PII handling belongs before indexing and telemetry. Interview focus: explain where this component sits, how it fails safely and how it is rolled back.
A26: W2-08 | B26: Week 2 | C26: 8 | D26: MUST | E26: Authorization | F26: Enforce tenant/classification filters before vector search. | G26: The model cannot be trusted to enforce access control. | H26: Codex (code) + User (execute) | I26: 1 | J26: W2-001 | K26: SEC-001 | L26: Cross-tenant query returns zero unauthorized chunks. | M26: pytest tests/security/test_tenant_isolation.py -q | N26: 100% isolation test passes. | O26: docs/test-evidence/W2-08-isolation.txt | P26: ADR-006 | Q26: W2-04 | R26: Disable retrieval endpoint and restore last-known-good filter implementation. | S26: Done | U26: Week 2 Authorization task in the end-to-end architecture. After Code Edit Approval, Codex writes only the approved code/configuration/test code for “Enforce tenant/classification filters before vector search.”; you run the verification/deployment commands and return the results. Business value: The model cannot be trusted to enforce access control. Interview focus: explain where this component sits, how it fails safely and how it is rolled back.
A27: W2-09 | B27: Week 2 | C27: 9 | D27: MUST | E27: Feature proof | F27: Ingest approved sample corpus and verify top-5 retrieval. | G27: This is the first measurable RAG foundation outcome. | H27: User (execute) + Codex (guide/code) | I27: 1 | J27: W2-004 | K27: DATA-001, EVAL-001 | L27: Expected source appears in top 5 for representative questions. | M27: TEST-001 — ORDERED OWNER EXECUTION (GUIDANCE; NOT A RUNNABLE BATCH) Codex derives each exact command from the current repository-configured scope, explains purpose, expected result, access/cost/privacy/risk and stop condition, and waits for complete owner output before issuing the next command. Retain this task-specific check order: 1. python -m enterprise_ai.ingestion.pipeline ingest --source data/sample --tenant demo 2. pytest tests/feature/test_local_retrieval.py -q On FAIL or INDETERMINATE: stop; perform a complete read-only root-cause, producer-consumer and approval-gate audit; request one consolidated remediation approval; never self-remediate. After successful checks, rollback/teardown and zero-residue verification are separate owner commands, also issued one at a time. | N27: Manifest, retrieval scores and source IDs are captured. | O27: docs/test-evidence/W2-09-retrieval.json | P27: ADR-003, ADR-017 | Q27: W2-03:W2-08 | R27: Delete test collection/volume and restore previous config. | S27: Done | U27: Week 2 Feature proof task in the end-to-end architecture. After Code Edit Approval, Codex writes only the approved code/configuration/test code for “Ingest approved sample corpus and verify top-5 retrieval.”; you run the verification/deployment commands and return the results. Business value: This is the first measurable RAG foundation outcome. Interview focus: explain where this component sits, how it fails safely and how it is rolled back.
A28: W2-10 | B28: Week 2 | C28: 10 | D28: MUST | E28: Reversibility | F28: Run local deploy, rollback and complete removal drill. | G28: A working feature is incomplete until it can be removed cleanly. | H28: User (execute) + Codex (guide/code) | I28: 1 | J28: W2-004 | K28: DEST-001 | L28: Previous configuration works after rollback; teardown leaves no local residue. | M28: TEST-001 — ORDERED OWNER EXECUTION (GUIDANCE; NOT A RUNNABLE BATCH) Codex derives each exact command from the current repository-configured scope, explains purpose, expected result, access/cost/privacy/risk and stop condition, and waits for complete owner output before issuing the next command. Retain this task-specific check order: 1. make rollback-local 2. make destroy-local 3. make verify-clean-local On FAIL or INDETERMINATE: stop; perform a complete read-only root-cause, producer-consumer and approval-gate audit; request one consolidated remediation approval; never self-remediate. After successful checks, rollback/teardown and zero-residue verification are separate owner commands, also issued one at a time. | N28: No project container, volume or network remains. | O28: docs/rollback-records/W2-local.md | P28: ADR-012, ADR-013 | Q28: W2-09 | R28: Recreate from pinned Compose/config and re-run feature test. | S28: Done | U28: Week 2 Reversibility task in the end-to-end architecture. After Code Edit Approval, Codex writes only the approved code/configuration/test code for “Run local deploy, rollback and complete removal drill.”; you run the verification/deployment commands and return the results. Business value: A working feature is incomplete until it can be removed cleanly. Interview focus: explain where this component sits, how it fails safely and how it is rolled back.
A29: W2-11 | B29: Week 2 | C29: 11 | D29: SHOULD | E29: Learning checkpoint | F29: Explain embeddings, cosine similarity, chunk size/overlap and metadata filtering. | G29: The workbook is also an interview/reference learning plan. | H29: User | I29: 0.75 | J29: W2-LEARN-001 | K29: None | L29: Five-minute explanation uses current implementation evidence. | M29: Owner records the five-minute teach-back notes in docs/architecture/local-retrieval.md | N29: Explanation connects decisions to quality, security and cost. | O29: docs/architecture/local-retrieval.md | P29: ADR-002, ADR-003, ADR-006 | Q29: W2-09 | R29: Revise ADR/notes; do not change code without a feature cycle. | S29: Done | U29: Week 2 owner decision/checkpoint in Learning checkpoint. You choose, approve or execute “Explain embeddings, cosine similarity, chunk size/overlap and metadata filtering.” because the decision affects downstream architecture and risk. Codex explains alternatives and may draft approved wording only under the proper approval stage. Business value: The workbook is also an interview/reference learning plan. Interview focus: explain the decision, trade-off and downstream consequence.
A30: W2-12 | B30: Week 2 | C30: 12 | D30: MUST | E30: Checkpoint | F30: Approve local retrieval gate and Week 3 inputs. | G30: Prevents LLM work from hiding retrieval defects. | H30: User | I30: 0.75 | J30: W2-REVIEW-001 | K30: BED-001, EVAL-001 | L30: All MUST tests and cleanup evidence pass. | M30: TEST-001 — ORDERED OWNER EXECUTION (GUIDANCE; NOT A RUNNABLE BATCH) Codex derives each exact command from the current repository-configured scope, explains purpose, expected result, access/cost/privacy/risk and stop condition, and waits for complete owner output before issuing the next command. Retain this task-specific check order: 1. make test 2. make verify-clean-local On FAIL or INDETERMINATE: stop; perform a complete read-only root-cause, producer-consumer and approval-gate audit; request one consolidated remediation approval; never self-remediate. After successful checks, rollback/teardown and zero-residue verification are separate owner commands, also issued one at a time. | N30: Owner sign-off; Bedrock/evaluation TODOs resolved or explicitly mocked. | O30: docs/deployment-records/W2-signoff.md | P30: ADR-016 | Q30: W2-01:W2-11 | R30: Remain on local retrieval until the gate passes. | S30: Done | U30: Week 2 business/decision documentation task in Checkpoint. The owner provides or approves the facts; after Document Writing Approval, Codex may draft only the approved business-first documentation. No code or command execution is permitted. Business value: Prevents LLM work from hiding retrieval defects. Interview focus: explain the decision, its alternatives and downstream impact.
A31: W2-13 | B31: Week 2 | C31: 13 | D31: MUST | E31: Weekly learning | F31: Complete the Week 2 local retrieval business, architecture and interview teach-back. | G31: Converts vector retrieval, ingestion, privacy and authorization work into an end-to-end business explanation. | H31: User (execute) + Codex (guide/code) | I31: 1 | J31: WEEKLY-LEARN-001 | K31: None | L31: Owner explains document-to-vector-to-authorized-retrieval flow, Qdrant role, failure handling and three interview answers. | M31: Owner completes the teach-back and records notes in docs/learning/W2-learning-review.md | N31: Business summary, technical deep-dive, layman analogy, decision recap and interview Q&A completed. | O31: docs/learning/W2-learning-review.md | P31: ADR-002, ADR-003, ADR-006 | Q31: W2-12 | R31: No runtime rollback; revise the learning note through document approval if inaccurate. | S31: Done | T31: Mandatory learning gate before Week 3. | U31: Week 2 learning gate after all implementation and checkpoint work. Codex teaches the business outcome and architecture; the owner completes a teach-back and interview practice. No runtime action is permitted. Business value: converts completed work into reusable understanding and decision ownership.
A32: W3-01 | B32: Week 3 | C32: 1 | D32: MUST | E32: LLM contract | F32: Create provider-neutral chat/tool/usage types and fake provider. | G32: RAG logic should not depend on Bedrock response formats. | H32: Codex (code) + User (execute) | I32: 1 | J32: W3-001 | K32: BED-001 | L32: Fake tests cover success, timeout and malformed response. | M32: pytest tests/unit/test_llm_provider.py -q | N32: Normalized errors and usage fields are stable. | O32: docs/test-evidence/W3-01-llm-contract.txt | P32: ADR-002, ADR-004 | Q32: W2-13 | R32: Switch configuration back to fake provider. | S32: Done | U32: Week 3 LLM contract task in the end-to-end architecture. After Code Edit Approval, Codex writes only the approved code/configuration/test code for “Create provider-neutral chat/tool/usage types and fake provider.”; you run the verification/deployment commands and return the results. Business value: RAG logic should not depend on Bedrock response formats. Interview focus: explain where this component sits, how it fails safely and how it is rolled back.
A33: W3-02 | B33: Week 3 | C33: 2 | D33: MUST | E33: AWS AI adapter | F33: Implement Bedrock adapter behind marked integration tests. | G33: Bedrock is the primary AWS model boundary without GPU operations. | H33: Codex (code) + User (execute) | I33: 1.25 | J33: W3-001 | K33: AWS-002, BED-001 | L33: Adapter has deadlines/retry caps and no hard-coded model ID. | M33: pytest tests/unit/test_bedrock_adapter.py -q | N33: Offline tests pass; live test is skipped unless explicitly enabled. | O33: docs/test-evidence/W3-02-bedrock.txt | P33: ADR-004 | Q33: W3-01 | R33: Set LLM_PROVIDER=fake; revoke test session if created. | S33: Done | U33: Week 3 AWS AI adapter task in the end-to-end architecture. After Code Edit Approval, Codex writes only the approved code/configuration/test code for “Implement Bedrock adapter behind marked integration tests.”; you run the verification/deployment commands and return the results. Business value: Bedrock is the primary AWS model boundary without GPU operations. Interview focus: explain where this component sits, how it fails safely and how it is rolled back.
A34: W3-03 | B34: Week 3 | C34: 3 | D34: MUST | E34: Prompt boundary | F34: Create versioned evidence-bound prompt template. | G34: Retrieved documents are data, never instructions. | H34: Codex (code) + User (execute) | I34: 0.75 | J34: W3-001 | K34: None | L34: Prompt clearly delimits evidence and demands citations/abstention. | M34: pytest tests/unit/test_prompt_template.py -q | N34: Injection fixture cannot override system policy. | O34: docs/test-evidence/W3-03-prompt.txt | P34: ADR-006, ADR-017 | Q34: W3-01 | R34: Restore previous approved prompt version. | S34: Done | U34: Week 3 Prompt boundary task in the end-to-end architecture. After Code Edit Approval, Codex writes only the approved code/configuration/test code for “Create versioned evidence-bound prompt template.”; you run the verification/deployment commands and return the results. Business value: Retrieved documents are data, never instructions. Interview focus: explain where this component sits, how it fails safely and how it is rolled back.
A35: W3-04 | B35: Week 3 | C35: 4 | D35: MUST | E35: RAG pipeline | F35: Authorize, retrieve, grade, generate and validate citations. | G35: This is the core safe-answer path. | H35: Codex (code) + User (execute) | I35: 1.5 | J35: W3-001 | K35: RAG-001 | L35: Structured Answer contains only supplied source IDs. | M35: pytest tests/unit/test_rag_pipeline.py -q | N35: Good evidence answers; low evidence abstains. | O35: docs/test-evidence/W3-04-rag.txt | P35: ADR-006, ADR-017 | Q35: W3-01:W3-03,W2-09 | R35: Switch to last-known-good prompt/model/retriever configuration. | S35: Done | U35: Week 3 RAG pipeline task in the end-to-end architecture. After Code Edit Approval, Codex writes only the approved code/configuration/test code for “Authorize, retrieve, grade, generate and validate citations.”; you run the verification/deployment commands and return the results. Business value: This is the core safe-answer path. Interview focus: explain where this component sits, how it fails safely and how it is rolled back.
A36: W3-05 | B36: Week 3 | C36: 5 | D36: MUST | E36: Guardrails | F36: Add deterministic input/output/citation safety checks. | G36: Deterministic policy must surround probabilistic generation. | H36: Codex (code) + User (execute) | I36: 1 | J36: W3-003 | K36: SEC-001, DATA-002 | L36: Malformed, unauthorized and uncited outputs fail safely. | M36: pytest tests/security tests/unit/test_guardrails.py -q | N36: Security suite passes with redacted logs. | O36: docs/test-evidence/W3-05-guardrails.txt | P36: ADR-006 | Q36: W3-04 | R36: Disable affected model route and return safe refusal. | S36: Done | U36: Week 3 Guardrails task in the end-to-end architecture. After Code Edit Approval, Codex writes only the approved code/configuration/test code for “Add deterministic input/output/citation safety checks.”; you run the verification/deployment commands and return the results. Business value: Deterministic policy must surround probabilistic generation. Interview focus: explain where this component sits, how it fails safely and how it is rolled back.
